2022-07-27 15:43:03 ERROR (MainThread) [homeassistant.components.sensor] Error adding entities for domain sensor with platform pi_hole
Traceback (most recent call last):
  File "/usr/src/homeassistant/homeassistant/helpers/entity_platform.py", line 397, in async_add_entities
    await asyncio.gather(*tasks)
  File "/usr/src/homeassistant/homeassistant/helpers/entity_platform.py", line 641, in _async_add_entity
    await entity.add_to_platform_finish()
  File "/usr/src/homeassistant/homeassistant/helpers/entity.py", line 776, in add_to_platform_finish
    self.async_write_ha_state()
  File "/usr/src/homeassistant/homeassistant/helpers/entity.py", line 532, in async_write_ha_state
    self._async_write_ha_state()
  File "/usr/src/homeassistant/homeassistant/helpers/entity.py", line 570, in _async_write_ha_state
    state = self._stringify_state(available)
  File "/usr/src/homeassistant/homeassistant/helpers/entity.py", line 538, in _stringify_state
    if (state := self.state) is None:
  File "/usr/src/homeassistant/homeassistant/components/sensor/__init__.py", line 388, in state
    value = self.native_value
  File "/usr/src/homeassistant/homeassistant/components/pi_hole/sensor.py", line 69, in native_value
    return round(self.api.data[self.entity_description.key], 2)
KeyError: 'ads_blocked_today'
2022-07-27 15:43:03 ERROR (MainThread) [homeassistant.components.sensor] Error while setting up pi_hole platform for sensor
Traceback (most recent call last):
  File "/usr/src/homeassistant/homeassistant/helpers/entity_platform.py", line 258, in _async_setup_platform
    await asyncio.gather(*pending)
  File "/usr/src/homeassistant/homeassistant/helpers/entity_platform.py", line 397, in async_add_entities
    await asyncio.gather(*tasks)
  File "/usr/src/homeassistant/homeassistant/helpers/entity_platform.py", line 641, in _async_add_entity
    await entity.add_to_platform_finish()
  File "/usr/src/homeassistant/homeassistant/helpers/entity.py", line 776, in add_to_platform_finish
    self.async_write_ha_state()
  File "/usr/src/homeassistant/homeassistant/helpers/entity.py", line 532, in async_write_ha_state
    self._async_write_ha_state()
  File "/usr/src/homeassistant/homeassistant/helpers/entity.py", line 570, in _async_write_ha_state
    state = self._stringify_state(available)
  File "/usr/src/homeassistant/homeassistant/helpers/entity.py", line 538, in _stringify_state
    if (state := self.state) is None:
  File "/usr/src/homeassistant/homeassistant/components/sensor/__init__.py", line 388, in state
    value = self.native_value
  File "/usr/src/homeassistant/homeassistant/components/pi_hole/sensor.py", line 69, in native_value
    return round(self.api.data[self.entity_description.key], 2)
KeyError: 'ads_blocked_today'
2022-07-27 15:43:03 ERROR (MainThread) [homeassistant.components.binary_sensor] pi_hole: Error on device update!
Traceback (most recent call last):
  File "/usr/src/homeassistant/homeassistant/helpers/entity_platform.py", line 446, in _async_add_entity
    await entity.async_device_update(warning=False)
  File "/usr/src/homeassistant/homeassistant/helpers/entity.py", line 702, in async_device_update
    await task
  File "/usr/src/homeassistant/homeassistant/helpers/update_coordinator.py", line 350, in async_update
    await self.coordinator.async_request_refresh()
  File "/usr/src/homeassistant/homeassistant/helpers/update_coordinator.py", line 158, in async_request_refresh
    await self._debounced_refresh.async_call()
  File "/usr/src/homeassistant/homeassistant/helpers/debounce.py", line 78, in async_call
    await task
  File "/usr/src/homeassistant/homeassistant/helpers/update_coordinator.py", line 182, in async_refresh
    await self._async_refresh(log_failures=True)
  File "/usr/src/homeassistant/homeassistant/helpers/update_coordinator.py", line 283, in _async_refresh
    self.async_update_listeners()
  File "/usr/src/homeassistant/homeassistant/helpers/update_coordinator.py", line 110, in async_update_listeners
    update_callback()
  File "/usr/src/homeassistant/homeassistant/helpers/update_coordinator.py", line 339, in _handle_coordinator_update
    self.async_write_ha_state()
  File "/usr/src/homeassistant/homeassistant/helpers/entity.py", line 532, in async_write_ha_state
    self._async_write_ha_state()
  File "/usr/src/homeassistant/homeassistant/helpers/entity.py", line 570, in _async_write_ha_state
    state = self._stringify_state(available)
  File "/usr/src/homeassistant/homeassistant/helpers/entity.py", line 538, in _stringify_state
    if (state := self.state) is None:
  File "/usr/src/homeassistant/homeassistant/components/sensor/__init__.py", line 388, in state
    value = self.native_value
  File "/usr/src/homeassistant/homeassistant/components/pi_hole/sensor.py", line 69, in native_value
    return round(self.api.data[self.entity_description.key], 2)
KeyError: 'ads_blocked_today'
2022-07-27 15:48:03 ERROR (MainThread) [homeassistant] Error doing job: Task exception was never retrieved
Traceback (most recent call last):
  File "/usr/src/homeassistant/homeassistant/helpers/update_coordinator.py", line 151, in _handle_refresh_interval
    await self._async_refresh(log_failures=True, scheduled=True)
  File "/usr/src/homeassistant/homeassistant/helpers/update_coordinator.py", line 283, in _async_refresh
    self.async_update_listeners()
  File "/usr/src/homeassistant/homeassistant/helpers/update_coordinator.py", line 110, in async_update_listeners
    update_callback()
  File "/usr/src/homeassistant/homeassistant/helpers/update_coordinator.py", line 339, in _handle_coordinator_update
    self.async_write_ha_state()
  File "/usr/src/homeassistant/homeassistant/helpers/entity.py", line 532, in async_write_ha_state
    self._async_write_ha_state()
  File "/usr/src/homeassistant/homeassistant/helpers/entity.py", line 570, in _async_write_ha_state
    state = self._stringify_state(available)
  File "/usr/src/homeassistant/homeassistant/helpers/entity.py", line 538, in _stringify_state
    if (state := self.state) is None:
  File "/usr/src/homeassistant/homeassistant/components/sensor/__init__.py", line 388, in state
    value = self.native_value
  File "/usr/src/homeassistant/homeassistant/components/pi_hole/sensor.py", line 69, in native_value
    return round(self.api.data[self.entity_description.key], 2)
KeyError: 'ads_blocked_today'
2022-07-27 15:53:03 ERROR (MainThread) [homeassistant] Error doing job: Task exception was never retrieved
Traceback (most recent call last):
  File "/usr/src/homeassistant/homeassistant/helpers/update_coordinator.py", line 151, in _handle_refresh_interval
    await self._async_refresh(log_failures=True, scheduled=True)
  File "/usr/src/homeassistant/homeassistant/helpers/update_coordinator.py", line 283, in _async_refresh
    self.async_update_listeners()
  File "/usr/src/homeassistant/homeassistant/helpers/update_coordinator.py", line 110, in async_update_listeners
    update_callback()
  File "/usr/src/homeassistant/homeassistant/helpers/update_coordinator.py", line 339, in _handle_coordinator_update
    self.async_write_ha_state()
  File "/usr/src/homeassistant/homeassistant/helpers/entity.py", line 532, in async_write_ha_state
    self._async_write_ha_state()
  File "/usr/src/homeassistant/homeassistant/helpers/entity.py", line 570, in _async_write_ha_state
    state = self._stringify_state(available)
  File "/usr/src/homeassistant/homeassistant/helpers/entity.py", line 538, in _stringify_state
    if (state := self.state) is None:
  File "/usr/src/homeassistant/homeassistant/components/sensor/__init__.py", line 388, in state
    value = self.native_value
  File "/usr/src/homeassistant/homeassistant/components/pi_hole/sensor.py", line 69, in native_value
    return round(self.api.data[self.entity_description.key], 2)
KeyError: 'ads_blocked_today'
2022-07-27 15:58:03 ERROR (MainThread) [homeassistant] Error doing job: Task exception was never retrieved
Traceback (most recent call last):
  File "/usr/src/homeassistant/homeassistant/helpers/update_coordinator.py", line 151, in _handle_refresh_interval
    await self._async_refresh(log_failures=True, scheduled=True)
  File "/usr/src/homeassistant/homeassistant/helpers/update_coordinator.py", line 283, in _async_refresh
    self.async_update_listeners()
  File "/usr/src/homeassistant/homeassistant/helpers/update_coordinator.py", line 110, in async_update_listeners
    update_callback()
  File "/usr/src/homeassistant/homeassistant/helpers/update_coordinator.py", line 339, in _handle_coordinator_update
    self.async_write_ha_state()
  File "/usr/src/homeassistant/homeassistant/helpers/entity.py", line 532, in async_write_ha_state
    self._async_write_ha_state()
  File "/usr/src/homeassistant/homeassistant/helpers/entity.py", line 570, in _async_write_ha_state
    state = self._stringify_state(available)
  File "/usr/src/homeassistant/homeassistant/helpers/entity.py", line 538, in _stringify_state
    if (state := self.state) is None:
  File "/usr/src/homeassistant/homeassistant/components/sensor/__init__.py", line 388, in state
    value = self.native_value
  File "/usr/src/homeassistant/homeassistant/components/pi_hole/sensor.py", line 69, in native_value
    return round(self.api.data[self.entity_description.key], 2)
KeyError: 'ads_blocked_today'
2022-07-27 15:58:33 WARNING (SyncWorker_4) [homeassistant.components.rpi_power.binary_sensor] Under-voltage was detected. Consider getting a uninterruptible power supply for your Raspberry Pi.
2022-07-27 16:03:03 ERROR (MainThread) [homeassistant] Error doing job: Task exception was never retrieved
Traceback (most recent call last):
  File "/usr/src/homeassistant/homeassistant/helpers/update_coordinator.py", line 151, in _handle_refresh_interval
    await self._async_refresh(log_failures=True, scheduled=True)
  File "/usr/src/homeassistant/homeassistant/helpers/update_coordinator.py", line 283, in _async_refresh
    self.async_update_listeners()
  File "/usr/src/homeassistant/homeassistant/helpers/update_coordinator.py", line 110, in async_update_listeners
    update_callback()
  File "/usr/src/homeassistant/homeassistant/helpers/update_coordinator.py", line 339, in _handle_coordinator_update
    self.async_write_ha_state()
  File "/usr/src/homeassistant/homeassistant/helpers/entity.py", line 532, in async_write_ha_state
    self._async_write_ha_state()
  File "/usr/src/homeassistant/homeassistant/helpers/entity.py", line 570, in _async_write_ha_state
    state = self._stringify_state(available)
  File "/usr/src/homeassistant/homeassistant/helpers/entity.py", line 538, in _stringify_state
    if (state := self.state) is None:
  File "/usr/src/homeassistant/homeassistant/components/sensor/__init__.py", line 388, in state
    value = self.native_value
  File "/usr/src/homeassistant/homeassistant/components/pi_hole/sensor.py", line 69, in native_value
    return round(self.api.data[self.entity_description.key], 2)
KeyError: 'ads_blocked_today'
2022-07-27 16:08:03 ERROR (MainThread) [homeassistant] Error doing job: Task exception was never retrieved
Traceback (most recent call last):
  File "/usr/src/homeassistant/homeassistant/helpers/update_coordinator.py", line 151, in _handle_refresh_interval
    await self._async_refresh(log_failures=True, scheduled=True)
  File "/usr/src/homeassistant/homeassistant/helpers/update_coordinator.py", line 283, in _async_refresh
    self.async_update_listeners()
  File "/usr/src/homeassistant/homeassistant/helpers/update_coordinator.py", line 110, in async_update_listeners
    update_callback()
  File "/usr/src/homeassistant/homeassistant/helpers/update_coordinator.py", line 339, in _handle_coordinator_update
    self.async_write_ha_state()
  File "/usr/src/homeassistant/homeassistant/helpers/entity.py", line 532, in async_write_ha_state
    self._async_write_ha_state()
  File "/usr/src/homeassistant/homeassistant/helpers/entity.py", line 570, in _async_write_ha_state
    state = self._stringify_state(available)
  File "/usr/src/homeassistant/homeassistant/helpers/entity.py", line 538, in _stringify_state
    if (state := self.state) is None:
  File "/usr/src/homeassistant/homeassistant/components/sensor/__init__.py", line 388, in state
    value = self.native_value
  File "/usr/src/homeassistant/homeassistant/components/pi_hole/sensor.py", line 69, in native_value
    return round(self.api.data[self.entity_description.key], 2)
KeyError: 'ads_blocked_today'
2022-07-27 16:13:03 ERROR (MainThread) [homeassistant] Error doing job: Task exception was never retrieved
Traceback (most recent call last):
  File "/usr/src/homeassistant/homeassistant/helpers/update_coordinator.py", line 151, in _handle_refresh_interval
    await self._async_refresh(log_failures=True, scheduled=True)
  File "/usr/src/homeassistant/homeassistant/helpers/update_coordinator.py", line 283, in _async_refresh
    self.async_update_listeners()
  File "/usr/src/homeassistant/homeassistant/helpers/update_coordinator.py", line 110, in async_update_listeners
    update_callback()
  File "/usr/src/homeassistant/homeassistant/helpers/update_coordinator.py", line 339, in _handle_coordinator_update
    self.async_write_ha_state()
  File "/usr/src/homeassistant/homeassistant/helpers/entity.py", line 532, in async_write_ha_state
    self._async_write_ha_state()
  File "/usr/src/homeassistant/homeassistant/helpers/entity.py", line 570, in _async_write_ha_state
    state = self._stringify_state(available)
  File "/usr/src/homeassistant/homeassistant/helpers/entity.py", line 538, in _stringify_state
    if (state := self.state) is None:
  File "/usr/src/homeassistant/homeassistant/components/sensor/__init__.py", line 388, in state
    value = self.native_value
  File "/usr/src/homeassistant/homeassistant/components/pi_hole/sensor.py", line 69, in native_value
    return round(self.api.data[self.entity_description.key], 2)
KeyError: 'ads_blocked_today'
2022-07-27 16:18:03 ERROR (MainThread) [homeassistant] Error doing job: Task exception was never retrieved
Traceback (most recent call last):
  File "/usr/src/homeassistant/homeassistant/helpers/update_coordinator.py", line 151, in _handle_refresh_interval
    await self._async_refresh(log_failures=True, scheduled=True)
  File "/usr/src/homeassistant/homeassistant/helpers/update_coordinator.py", line 283, in _async_refresh
    self.async_update_listeners()
  File "/usr/src/homeassistant/homeassistant/helpers/update_coordinator.py", line 110, in async_update_listeners
    update_callback()
  File "/usr/src/homeassistant/homeassistant/helpers/update_coordinator.py", line 339, in _handle_coordinator_update
    self.async_write_ha_state()
  File "/usr/src/homeassistant/homeassistant/helpers/entity.py", line 532, in async_write_ha_state
    self._async_write_ha_state()
  File "/usr/src/homeassistant/homeassistant/helpers/entity.py", line 570, in _async_write_ha_state
    state = self._stringify_state(available)
  File "/usr/src/homeassistant/homeassistant/helpers/entity.py", line 538, in _stringify_state
    if (state := self.state) is None:
  File "/usr/src/homeassistant/homeassistant/components/sensor/__init__.py", line 388, in state
    value = self.native_value
  File "/usr/src/homeassistant/homeassistant/components/pi_hole/sensor.py", line 69, in native_value
    return round(self.api.data[self.entity_description.key], 2)
KeyError: 'ads_blocked_today'
2022-07-27 16:23:03 ERROR (MainThread) [homeassistant] Error doing job: Task exception was never retrieved
Traceback (most recent call last):
  File "/usr/src/homeassistant/homeassistant/helpers/update_coordinator.py", line 151, in _handle_refresh_interval
    await self._async_refresh(log_failures=True, scheduled=True)
  File "/usr/src/homeassistant/homeassistant/helpers/update_coordinator.py", line 283, in _async_refresh
    self.async_update_listeners()
  File "/usr/src/homeassistant/homeassistant/helpers/update_coordinator.py", line 110, in async_update_listeners
    update_callback()
  File "/usr/src/homeassistant/homeassistant/helpers/update_coordinator.py", line 339, in _handle_coordinator_update
    self.async_write_ha_state()
  File "/usr/src/homeassistant/homeassistant/helpers/entity.py", line 532, in async_write_ha_state
    self._async_write_ha_state()
  File "/usr/src/homeassistant/homeassistant/helpers/entity.py", line 570, in _async_write_ha_state
    state = self._stringify_state(available)
  File "/usr/src/homeassistant/homeassistant/helpers/entity.py", line 538, in _stringify_state
    if (state := self.state) is None:
  File "/usr/src/homeassistant/homeassistant/components/sensor/__init__.py", line 388, in state
    value = self.native_value
  File "/usr/src/homeassistant/homeassistant/components/pi_hole/sensor.py", line 69, in native_value
    return round(self.api.data[self.entity_description.key], 2)
KeyError: 'ads_blocked_today'
2022-07-27 16:28:03 ERROR (MainThread) [homeassistant] Error doing job: Task exception was never retrieved
Traceback (most recent call last):
  File "/usr/src/homeassistant/homeassistant/helpers/update_coordinator.py", line 151, in _handle_refresh_interval
    await self._async_refresh(log_failures=True, scheduled=True)
  File "/usr/src/homeassistant/homeassistant/helpers/update_coordinator.py", line 283, in _async_refresh
    self.async_update_listeners()
  File "/usr/src/homeassistant/homeassistant/helpers/update_coordinator.py", line 110, in async_update_listeners
    update_callback()
  File "/usr/src/homeassistant/homeassistant/helpers/update_coordinator.py", line 339, in _handle_coordinator_update
    self.async_write_ha_state()
  File "/usr/src/homeassistant/homeassistant/helpers/entity.py", line 532, in async_write_ha_state
    self._async_write_ha_state()
  File "/usr/src/homeassistant/homeassistant/helpers/entity.py", line 570, in _async_write_ha_state
    state = self._stringify_state(available)
  File "/usr/src/homeassistant/homeassistant/helpers/entity.py", line 538, in _stringify_state
    if (state := self.state) is None:
  File "/usr/src/homeassistant/homeassistant/components/sensor/__init__.py", line 388, in state
    value = self.native_value
  File "/usr/src/homeassistant/homeassistant/components/pi_hole/sensor.py", line 69, in native_value
    return round(self.api.data[self.entity_description.key], 2)
KeyError: 'ads_blocked_today'
2022-07-27 16:33:03 ERROR (MainThread) [homeassistant] Error doing job: Task exception was never retrieved
Traceback (most recent call last):
  File "/usr/src/homeassistant/homeassistant/helpers/update_coordinator.py", line 151, in _handle_refresh_interval
    await self._async_refresh(log_failures=True, scheduled=True)
  File "/usr/src/homeassistant/homeassistant/helpers/update_coordinator.py", line 283, in _async_refresh
    self.async_update_listeners()
  File "/usr/src/homeassistant/homeassistant/helpers/update_coordinator.py", line 110, in async_update_listeners
    update_callback()
  File "/usr/src/homeassistant/homeassistant/helpers/update_coordinator.py", line 339, in _handle_coordinator_update
    self.async_write_ha_state()
  File "/usr/src/homeassistant/homeassistant/helpers/entity.py", line 532, in async_write_ha_state
    self._async_write_ha_state()
  File "/usr/src/homeassistant/homeassistant/helpers/entity.py", line 570, in _async_write_ha_state
    state = self._stringify_state(available)
  File "/usr/src/homeassistant/homeassistant/helpers/entity.py", line 538, in _stringify_state
    if (state := self.state) is None:
  File "/usr/src/homeassistant/homeassistant/components/sensor/__init__.py", line 388, in state
    value = self.native_value
  File "/usr/src/homeassistant/homeassistant/components/pi_hole/sensor.py", line 69, in native_value
    return round(self.api.data[self.entity_description.key], 2)
KeyError: 'ads_blocked_today'
2022-07-27 16:38:03 ERROR (MainThread) [homeassistant] Error doing job: Task exception was never retrieved
Traceback (most recent call last):
  File "/usr/src/homeassistant/homeassistant/helpers/update_coordinator.py", line 151, in _handle_refresh_interval
    await self._async_refresh(log_failures=True, scheduled=True)
  File "/usr/src/homeassistant/homeassistant/helpers/update_coordinator.py", line 283, in _async_refresh
    self.async_update_listeners()
  File "/usr/src/homeassistant/homeassistant/helpers/update_coordinator.py", line 110, in async_update_listeners
    update_callback()
  File "/usr/src/homeassistant/homeassistant/helpers/update_coordinator.py", line 339, in _handle_coordinator_update
    self.async_write_ha_state()
  File "/usr/src/homeassistant/homeassistant/helpers/entity.py", line 532, in async_write_ha_state
    self._async_write_ha_state()
  File "/usr/src/homeassistant/homeassistant/helpers/entity.py", line 570, in _async_write_ha_state
    state = self._stringify_state(available)
  File "/usr/src/homeassistant/homeassistant/helpers/entity.py", line 538, in _stringify_state
    if (state := self.state) is None:
  File "/usr/src/homeassistant/homeassistant/components/sensor/__init__.py", line 388, in state
    value = self.native_value
  File "/usr/src/homeassistant/homeassistant/components/pi_hole/sensor.py", line 69, in native_value
    return round(self.api.data[self.entity_description.key], 2)
KeyError: 'ads_blocked_today'
2022-07-27 16:41:33 WARNING (SyncWorker_4) [homeassistant.components.rpi_power.binary_sensor] Under-voltage was detected. Consider getting a uninterruptible power supply for your Raspberry Pi.
2022-07-27 16:43:03 ERROR (MainThread) [homeassistant] Error doing job: Task exception was never retrieved
Traceback (most recent call last):
  File "/usr/src/homeassistant/homeassistant/helpers/update_coordinator.py", line 151, in _handle_refresh_interval
    await self._async_refresh(log_failures=True, scheduled=True)
  File "/usr/src/homeassistant/homeassistant/helpers/update_coordinator.py", line 283, in _async_refresh
    self.async_update_listeners()
  File "/usr/src/homeassistant/homeassistant/helpers/update_coordinator.py", line 110, in async_update_listeners
    update_callback()
  File "/usr/src/homeassistant/homeassistant/helpers/update_coordinator.py", line 339, in _handle_coordinator_update
    self.async_write_ha_state()
  File "/usr/src/homeassistant/homeassistant/helpers/entity.py", line 532, in async_write_ha_state
    self._async_write_ha_state()
  File "/usr/src/homeassistant/homeassistant/helpers/entity.py", line 570, in _async_write_ha_state
    state = self._stringify_state(available)
  File "/usr/src/homeassistant/homeassistant/helpers/entity.py", line 538, in _stringify_state
    if (state := self.state) is None:
  File "/usr/src/homeassistant/homeassistant/components/sensor/__init__.py", line 388, in state
    value = self.native_value
  File "/usr/src/homeassistant/homeassistant/components/pi_hole/sensor.py", line 69, in native_value
    return round(self.api.data[self.entity_description.key], 2)
KeyError: 'ads_blocked_today'
2022-07-27 16:48:03 ERROR (MainThread) [homeassistant] Error doing job: Task exception was never retrieved
Traceback (most recent call last):
  File "/usr/src/homeassistant/homeassistant/helpers/update_coordinator.py", line 151, in _handle_refresh_interval
    await self._async_refresh(log_failures=True, scheduled=True)
  File "/usr/src/homeassistant/homeassistant/helpers/update_coordinator.py", line 283, in _async_refresh
    self.async_update_listeners()
  File "/usr/src/homeassistant/homeassistant/helpers/update_coordinator.py", line 110, in async_update_listeners
    update_callback()
  File "/usr/src/homeassistant/homeassistant/helpers/update_coordinator.py", line 339, in _handle_coordinator_update
    self.async_write_ha_state()
  File "/usr/src/homeassistant/homeassistant/helpers/entity.py", line 532, in async_write_ha_state
    self._async_write_ha_state()
  File "/usr/src/homeassistant/homeassistant/helpers/entity.py", line 570, in _async_write_ha_state
    state = self._stringify_state(available)
  File "/usr/src/homeassistant/homeassistant/helpers/entity.py", line 538, in _stringify_state
    if (state := self.state) is None:
  File "/usr/src/homeassistant/homeassistant/components/sensor/__init__.py", line 388, in state
    value = self.native_value
  File "/usr/src/homeassistant/homeassistant/components/pi_hole/sensor.py", line 69, in native_value
    return round(self.api.data[self.entity_description.key], 2)
KeyError: 'ads_blocked_today'
2022-07-27 16:53:03 ERROR (MainThread) [homeassistant] Error doing job: Task exception was never retrieved
Traceback (most recent call last):
  File "/usr/src/homeassistant/homeassistant/helpers/update_coordinator.py", line 151, in _handle_refresh_interval
    await self._async_refresh(log_failures=True, scheduled=True)
  File "/usr/src/homeassistant/homeassistant/helpers/update_coordinator.py", line 283, in _async_refresh
    self.async_update_listeners()
  File "/usr/src/homeassistant/homeassistant/helpers/update_coordinator.py", line 110, in async_update_listeners
    update_callback()
  File "/usr/src/homeassistant/homeassistant/helpers/update_coordinator.py", line 339, in _handle_coordinator_update
    self.async_write_ha_state()
  File "/usr/src/homeassistant/homeassistant/helpers/entity.py", line 532, in async_write_ha_state
    self._async_write_ha_state()
  File "/usr/src/homeassistant/homeassistant/helpers/entity.py", line 570, in _async_write_ha_state
    state = self._stringify_state(available)
  File "/usr/src/homeassistant/homeassistant/helpers/entity.py", line 538, in _stringify_state
    if (state := self.state) is None:
  File "/usr/src/homeassistant/homeassistant/components/sensor/__init__.py", line 388, in state
    value = self.native_value
  File "/usr/src/homeassistant/homeassistant/components/pi_hole/sensor.py", line 69, in native_value
    return round(self.api.data[self.entity_description.key], 2)
KeyError: 'ads_blocked_today'
2022-07-27 16:53:03 WARNING (SyncWorker_1) [homeassistant.components.rpi_power.binary_sensor] Under-voltage was detected. Consider getting a uninterruptible power supply for your Raspberry Pi.
2022-07-27 16:58:03 ERROR (MainThread) [homeassistant] Error doing job: Task exception was never retrieved
Traceback (most recent call last):
  File "/usr/src/homeassistant/homeassistant/helpers/update_coordinator.py", line 151, in _handle_refresh_interval
    await self._async_refresh(log_failures=True, scheduled=True)
  File "/usr/src/homeassistant/homeassistant/helpers/update_coordinator.py", line 283, in _async_refresh
    self.async_update_listeners()
  File "/usr/src/homeassistant/homeassistant/helpers/update_coordinator.py", line 110, in async_update_listeners
    update_callback()
  File "/usr/src/homeassistant/homeassistant/helpers/update_coordinator.py", line 339, in _handle_coordinator_update
    self.async_write_ha_state()
  File "/usr/src/homeassistant/homeassistant/helpers/entity.py", line 532, in async_write_ha_state
    self._async_write_ha_state()
  File "/usr/src/homeassistant/homeassistant/helpers/entity.py", line 570, in _async_write_ha_state
    state = self._stringify_state(available)
  File "/usr/src/homeassistant/homeassistant/helpers/entity.py", line 538, in _stringify_state
    if (state := self.state) is None:
  File "/usr/src/homeassistant/homeassistant/components/sensor/__init__.py", line 388, in state
    value = self.native_value
  File "/usr/src/homeassistant/homeassistant/components/pi_hole/sensor.py", line 69, in native_value
    return round(self.api.data[self.entity_description.key], 2)
KeyError: 'ads_blocked_today'
2022-07-27 17:03:03 ERROR (MainThread) [homeassistant] Error doing job: Task exception was never retrieved
Traceback (most recent call last):
  File "/usr/src/homeassistant/homeassistant/helpers/update_coordinator.py", line 151, in _handle_refresh_interval
    await self._async_refresh(log_failures=True, scheduled=True)
  File "/usr/src/homeassistant/homeassistant/helpers/update_coordinator.py", line 283, in _async_refresh
    self.async_update_listeners()
  File "/usr/src/homeassistant/homeassistant/helpers/update_coordinator.py", line 110, in async_update_listeners
    update_callback()
  File "/usr/src/homeassistant/homeassistant/helpers/update_coordinator.py", line 339, in _handle_coordinator_update
    self.async_write_ha_state()
  File "/usr/src/homeassistant/homeassistant/helpers/entity.py", line 532, in async_write_ha_state
    self._async_write_ha_state()
  File "/usr/src/homeassistant/homeassistant/helpers/entity.py", line 570, in _async_write_ha_state
    state = self._stringify_state(available)
  File "/usr/src/homeassistant/homeassistant/helpers/entity.py", line 538, in _stringify_state
    if (state := self.state) is None:
  File "/usr/src/homeassistant/homeassistant/components/sensor/__init__.py", line 388, in state
    value = self.native_value
  File "/usr/src/homeassistant/homeassistant/components/pi_hole/sensor.py", line 69, in native_value
    return round(self.api.data[self.entity_description.key], 2)
KeyError: 'ads_blocked_today'
2022-07-27 17:08:03 ERROR (MainThread) [homeassistant] Error doing job: Task exception was never retrieved
Traceback (most recent call last):
  File "/usr/src/homeassistant/homeassistant/helpers/update_coordinator.py", line 151, in _handle_refresh_interval
    await self._async_refresh(log_failures=True, scheduled=True)
  File "/usr/src/homeassistant/homeassistant/helpers/update_coordinator.py", line 283, in _async_refresh
    self.async_update_listeners()
  File "/usr/src/homeassistant/homeassistant/helpers/update_coordinator.py", line 110, in async_update_listeners
    update_callback()
  File "/usr/src/homeassistant/homeassistant/helpers/update_coordinator.py", line 339, in _handle_coordinator_update
    self.async_write_ha_state()
  File "/usr/src/homeassistant/homeassistant/helpers/entity.py", line 532, in async_write_ha_state
    self._async_write_ha_state()
  File "/usr/src/homeassistant/homeassistant/helpers/entity.py", line 570, in _async_write_ha_state
    state = self._stringify_state(available)
  File "/usr/src/homeassistant/homeassistant/helpers/entity.py", line 538, in _stringify_state
    if (state := self.state) is None:
  File "/usr/src/homeassistant/homeassistant/components/sensor/__init__.py", line 388, in state
    value = self.native_value
  File "/usr/src/homeassistant/homeassistant/components/pi_hole/sensor.py", line 69, in native_value
    return round(self.api.data[self.entity_description.key], 2)
KeyError: 'ads_blocked_today'
2022-07-27 17:13:03 ERROR (MainThread) [homeassistant] Error doing job: Task exception was never retrieved
Traceback (most recent call last):
  File "/usr/src/homeassistant/homeassistant/helpers/update_coordinator.py", line 151, in _handle_refresh_interval
    await self._async_refresh(log_failures=True, scheduled=True)
  File "/usr/src/homeassistant/homeassistant/helpers/update_coordinator.py", line 283, in _async_refresh
    self.async_update_listeners()
  File "/usr/src/homeassistant/homeassistant/helpers/update_coordinator.py", line 110, in async_update_listeners
    update_callback()
  File "/usr/src/homeassistant/homeassistant/helpers/update_coordinator.py", line 339, in _handle_coordinator_update
    self.async_write_ha_state()
  File "/usr/src/homeassistant/homeassistant/helpers/entity.py", line 532, in async_write_ha_state
    self._async_write_ha_state()
  File "/usr/src/homeassistant/homeassistant/helpers/entity.py", line 570, in _async_write_ha_state
    state = self._stringify_state(available)
  File "/usr/src/homeassistant/homeassistant/helpers/entity.py", line 538, in _stringify_state
    if (state := self.state) is None:
  File "/usr/src/homeassistant/homeassistant/components/sensor/__init__.py", line 388, in state
    value = self.native_value
  File "/usr/src/homeassistant/homeassistant/components/pi_hole/sensor.py", line 69, in native_value
    return round(self.api.data[self.entity_description.key], 2)
KeyError: 'ads_blocked_today'
2022-07-27 17:18:03 ERROR (MainThread) [homeassistant] Error doing job: Task exception was never retrieved
Traceback (most recent call last):
  File "/usr/src/homeassistant/homeassistant/helpers/update_coordinator.py", line 151, in _handle_refresh_interval
    await self._async_refresh(log_failures=True, scheduled=True)
  File "/usr/src/homeassistant/homeassistant/helpers/update_coordinator.py", line 283, in _async_refresh
    self.async_update_listeners()
  File "/usr/src/homeassistant/homeassistant/helpers/update_coordinator.py", line 110, in async_update_listeners
    update_callback()
  File "/usr/src/homeassistant/homeassistant/helpers/update_coordinator.py", line 339, in _handle_coordinator_update
    self.async_write_ha_state()
  File "/usr/src/homeassistant/homeassistant/helpers/entity.py", line 532, in async_write_ha_state
    self._async_write_ha_state()
  File "/usr/src/homeassistant/homeassistant/helpers/entity.py", line 570, in _async_write_ha_state
    state = self._stringify_state(available)
  File "/usr/src/homeassistant/homeassistant/helpers/entity.py", line 538, in _stringify_state
    if (state := self.state) is None:
  File "/usr/src/homeassistant/homeassistant/components/sensor/__init__.py", line 388, in state
    value = self.native_value
  File "/usr/src/homeassistant/homeassistant/components/pi_hole/sensor.py", line 69, in native_value
    return round(self.api.data[self.entity_description.key], 2)
KeyError: 'ads_blocked_today'
2022-07-27 17:23:03 ERROR (MainThread) [homeassistant] Error doing job: Task exception was never retrieved
Traceback (most recent call last):
  File "/usr/src/homeassistant/homeassistant/helpers/update_coordinator.py", line 151, in _handle_refresh_interval
    await self._async_refresh(log_failures=True, scheduled=True)
  File "/usr/src/homeassistant/homeassistant/helpers/update_coordinator.py", line 283, in _async_refresh
    self.async_update_listeners()
  File "/usr/src/homeassistant/homeassistant/helpers/update_coordinator.py", line 110, in async_update_listeners
    update_callback()
  File "/usr/src/homeassistant/homeassistant/helpers/update_coordinator.py", line 339, in _handle_coordinator_update
    self.async_write_ha_state()
  File "/usr/src/homeassistant/homeassistant/helpers/entity.py", line 532, in async_write_ha_state
    self._async_write_ha_state()
  File "/usr/src/homeassistant/homeassistant/helpers/entity.py", line 570, in _async_write_ha_state
    state = self._stringify_state(available)
  File "/usr/src/homeassistant/homeassistant/helpers/entity.py", line 538, in _stringify_state
    if (state := self.state) is None:
  File "/usr/src/homeassistant/homeassistant/components/sensor/__init__.py", line 388, in state
    value = self.native_value
  File "/usr/src/homeassistant/homeassistant/components/pi_hole/sensor.py", line 69, in native_value
    return round(self.api.data[self.entity_description.key], 2)
KeyError: 'ads_blocked_today'
2022-07-27 17:28:03 ERROR (MainThread) [homeassistant] Error doing job: Task exception was never retrieved
Traceback (most recent call last):
  File "/usr/src/homeassistant/homeassistant/helpers/update_coordinator.py", line 151, in _handle_refresh_interval
    await self._async_refresh(log_failures=True, scheduled=True)
  File "/usr/src/homeassistant/homeassistant/helpers/update_coordinator.py", line 283, in _async_refresh
    self.async_update_listeners()
  File "/usr/src/homeassistant/homeassistant/helpers/update_coordinator.py", line 110, in async_update_listeners
    update_callback()
  File "/usr/src/homeassistant/homeassistant/helpers/update_coordinator.py", line 339, in _handle_coordinator_update
    self.async_write_ha_state()
  File "/usr/src/homeassistant/homeassistant/helpers/entity.py", line 532, in async_write_ha_state
    self._async_write_ha_state()
  File "/usr/src/homeassistant/homeassistant/helpers/entity.py", line 570, in _async_write_ha_state
    state = self._stringify_state(available)
  File "/usr/src/homeassistant/homeassistant/helpers/entity.py", line 538, in _stringify_state
    if (state := self.state) is None:
  File "/usr/src/homeassistant/homeassistant/components/sensor/__init__.py", line 388, in state
    value = self.native_value
  File "/usr/src/homeassistant/homeassistant/components/pi_hole/sensor.py", line 69, in native_value
    return round(self.api.data[self.entity_description.key], 2)
KeyError: 'ads_blocked_today'
2022-07-27 17:33:03 ERROR (MainThread) [homeassistant] Error doing job: Task exception was never retrieved
Traceback (most recent call last):
  File "/usr/src/homeassistant/homeassistant/helpers/update_coordinator.py", line 151, in _handle_refresh_interval
    await self._async_refresh(log_failures=True, scheduled=True)
  File "/usr/src/homeassistant/homeassistant/helpers/update_coordinator.py", line 283, in _async_refresh
    self.async_update_listeners()
  File "/usr/src/homeassistant/homeassistant/helpers/update_coordinator.py", line 110, in async_update_listeners
    update_callback()
  File "/usr/src/homeassistant/homeassistant/helpers/update_coordinator.py", line 339, in _handle_coordinator_update
    self.async_write_ha_state()
  File "/usr/src/homeassistant/homeassistant/helpers/entity.py", line 532, in async_write_ha_state
    self._async_write_ha_state()
  File "/usr/src/homeassistant/homeassistant/helpers/entity.py", line 570, in _async_write_ha_state
    state = self._stringify_state(available)
  File "/usr/src/homeassistant/homeassistant/helpers/entity.py", line 538, in _stringify_state
    if (state := self.state) is None:
  File "/usr/src/homeassistant/homeassistant/components/sensor/__init__.py", line 388, in state
    value = self.native_value
  File "/usr/src/homeassistant/homeassistant/components/pi_hole/sensor.py", line 69, in native_value
    return round(self.api.data[self.entity_description.key], 2)
KeyError: 'ads_blocked_today'
2022-07-27 17:38:03 ERROR (MainThread) [homeassistant] Error doing job: Task exception was never retrieved
Traceback (most recent call last):
  File "/usr/src/homeassistant/homeassistant/helpers/update_coordinator.py", line 151, in _handle_refresh_interval
    await self._async_refresh(log_failures=True, scheduled=True)
  File "/usr/src/homeassistant/homeassistant/helpers/update_coordinator.py", line 283, in _async_refresh
    self.async_update_listeners()
  File "/usr/src/homeassistant/homeassistant/helpers/update_coordinator.py", line 110, in async_update_listeners
    update_callback()
  File "/usr/src/homeassistant/homeassistant/helpers/update_coordinator.py", line 339, in _handle_coordinator_update
    self.async_write_ha_state()
  File "/usr/src/homeassistant/homeassistant/helpers/entity.py", line 532, in async_write_ha_state
    self._async_write_ha_state()
  File "/usr/src/homeassistant/homeassistant/helpers/entity.py", line 570, in _async_write_ha_state
    state = self._stringify_state(available)
  File "/usr/src/homeassistant/homeassistant/helpers/entity.py", line 538, in _stringify_state
    if (state := self.state) is None:
  File "/usr/src/homeassistant/homeassistant/components/sensor/__init__.py", line 388, in state
    value = self.native_value
  File "/usr/src/homeassistant/homeassistant/components/pi_hole/sensor.py", line 69, in native_value
    return round(self.api.data[self.entity_description.key], 2)
KeyError: 'ads_blocked_today'
2022-07-27 17:40:33 WARNING (SyncWorker_4) [homeassistant.components.rpi_power.binary_sensor] Under-voltage was detected. Consider getting a uninterruptible power supply for your Raspberry Pi.
2022-07-27 17:43:03 ERROR (MainThread) [homeassistant] Error doing job: Task exception was never retrieved
Traceback (most recent call last):
  File "/usr/src/homeassistant/homeassistant/helpers/update_coordinator.py", line 151, in _handle_refresh_interval
    await self._async_refresh(log_failures=True, scheduled=True)
  File "/usr/src/homeassistant/homeassistant/helpers/update_coordinator.py", line 283, in _async_refresh
    self.async_update_listeners()
  File "/usr/src/homeassistant/homeassistant/helpers/update_coordinator.py", line 110, in async_update_listeners
    update_callback()
  File "/usr/src/homeassistant/homeassistant/helpers/update_coordinator.py", line 339, in _handle_coordinator_update
    self.async_write_ha_state()
  File "/usr/src/homeassistant/homeassistant/helpers/entity.py", line 532, in async_write_ha_state
    self._async_write_ha_state()
  File "/usr/src/homeassistant/homeassistant/helpers/entity.py", line 570, in _async_write_ha_state
    state = self._stringify_state(available)
  File "/usr/src/homeassistant/homeassistant/helpers/entity.py", line 538, in _stringify_state
    if (state := self.state) is None:
  File "/usr/src/homeassistant/homeassistant/components/sensor/__init__.py", line 388, in state
    value = self.native_value
  File "/usr/src/homeassistant/homeassistant/components/pi_hole/sensor.py", line 69, in native_value
    return round(self.api.data[self.entity_description.key], 2)
KeyError: 'ads_blocked_today'
2022-07-27 17:48:03 ERROR (MainThread) [homeassistant] Error doing job: Task exception was never retrieved
Traceback (most recent call last):
  File "/usr/src/homeassistant/homeassistant/helpers/update_coordinator.py", line 151, in _handle_refresh_interval
    await self._async_refresh(log_failures=True, scheduled=True)
  File "/usr/src/homeassistant/homeassistant/helpers/update_coordinator.py", line 283, in _async_refresh
    self.async_update_listeners()
  File "/usr/src/homeassistant/homeassistant/helpers/update_coordinator.py", line 110, in async_update_listeners
    update_callback()
  File "/usr/src/homeassistant/homeassistant/helpers/update_coordinator.py", line 339, in _handle_coordinator_update
    self.async_write_ha_state()
  File "/usr/src/homeassistant/homeassistant/helpers/entity.py", line 532, in async_write_ha_state
    self._async_write_ha_state()
  File "/usr/src/homeassistant/homeassistant/helpers/entity.py", line 570, in _async_write_ha_state
    state = self._stringify_state(available)
  File "/usr/src/homeassistant/homeassistant/helpers/entity.py", line 538, in _stringify_state
    if (state := self.state) is None:
  File "/usr/src/homeassistant/homeassistant/components/sensor/__init__.py", line 388, in state
    value = self.native_value
  File "/usr/src/homeassistant/homeassistant/components/pi_hole/sensor.py", line 69, in native_value
    return round(self.api.data[self.entity_description.key], 2)
KeyError: 'ads_blocked_today'
2022-07-27 17:53:03 ERROR (MainThread) [homeassistant] Error doing job: Task exception was never retrieved
Traceback (most recent call last):
  File "/usr/src/homeassistant/homeassistant/helpers/update_coordinator.py", line 151, in _handle_refresh_interval
    await self._async_refresh(log_failures=True, scheduled=True)
  File "/usr/src/homeassistant/homeassistant/helpers/update_coordinator.py", line 283, in _async_refresh
    self.async_update_listeners()
  File "/usr/src/homeassistant/homeassistant/helpers/update_coordinator.py", line 110, in async_update_listeners
    update_callback()
  File "/usr/src/homeassistant/homeassistant/helpers/update_coordinator.py", line 339, in _handle_coordinator_update
    self.async_write_ha_state()
  File "/usr/src/homeassistant/homeassistant/helpers/entity.py", line 532, in async_write_ha_state
    self._async_write_ha_state()
  File "/usr/src/homeassistant/homeassistant/helpers/entity.py", line 570, in _async_write_ha_state
    state = self._stringify_state(available)
  File "/usr/src/homeassistant/homeassistant/helpers/entity.py", line 538, in _stringify_state
    if (state := self.state) is None:
  File "/usr/src/homeassistant/homeassistant/components/sensor/__init__.py", line 388, in state
    value = self.native_value
  File "/usr/src/homeassistant/homeassistant/components/pi_hole/sensor.py", line 69, in native_value
    return round(self.api.data[self.entity_description.key], 2)
KeyError: 'ads_blocked_today'
2022-07-27 17:58:03 ERROR (MainThread) [homeassistant] Error doing job: Task exception was never retrieved
Traceback (most recent call last):
  File "/usr/src/homeassistant/homeassistant/helpers/update_coordinator.py", line 151, in _handle_refresh_interval
    await self._async_refresh(log_failures=True, scheduled=True)
  File "/usr/src/homeassistant/homeassistant/helpers/update_coordinator.py", line 283, in _async_refresh
    self.async_update_listeners()
  File "/usr/src/homeassistant/homeassistant/helpers/update_coordinator.py", line 110, in async_update_listeners
    update_callback()
  File "/usr/src/homeassistant/homeassistant/helpers/update_coordinator.py", line 339, in _handle_coordinator_update
    self.async_write_ha_state()
  File "/usr/src/homeassistant/homeassistant/helpers/entity.py", line 532, in async_write_ha_state
    self._async_write_ha_state()
  File "/usr/src/homeassistant/homeassistant/helpers/entity.py", line 570, in _async_write_ha_state
    state = self._stringify_state(available)
  File "/usr/src/homeassistant/homeassistant/helpers/entity.py", line 538, in _stringify_state
    if (state := self.state) is None:
  File "/usr/src/homeassistant/homeassistant/components/sensor/__init__.py", line 388, in state
    value = self.native_value
  File "/usr/src/homeassistant/homeassistant/components/pi_hole/sensor.py", line 69, in native_value
    return round(self.api.data[self.entity_description.key], 2)
KeyError: 'ads_blocked_today'
2022-07-27 18:03:03 ERROR (MainThread) [homeassistant] Error doing job: Task exception was never retrieved
Traceback (most recent call last):
  File "/usr/src/homeassistant/homeassistant/helpers/update_coordinator.py", line 151, in _handle_refresh_interval
    await self._async_refresh(log_failures=True, scheduled=True)
  File "/usr/src/homeassistant/homeassistant/helpers/update_coordinator.py", line 283, in _async_refresh
    self.async_update_listeners()
  File "/usr/src/homeassistant/homeassistant/helpers/update_coordinator.py", line 110, in async_update_listeners
    update_callback()
  File "/usr/src/homeassistant/homeassistant/helpers/update_coordinator.py", line 339, in _handle_coordinator_update
    self.async_write_ha_state()
  File "/usr/src/homeassistant/homeassistant/helpers/entity.py", line 532, in async_write_ha_state
    self._async_write_ha_state()
  File "/usr/src/homeassistant/homeassistant/helpers/entity.py", line 570, in _async_write_ha_state
    state = self._stringify_state(available)
  File "/usr/src/homeassistant/homeassistant/helpers/entity.py", line 538, in _stringify_state
    if (state := self.state) is None:
  File "/usr/src/homeassistant/homeassistant/components/sensor/__init__.py", line 388, in state
    value = self.native_value
  File "/usr/src/homeassistant/homeassistant/components/pi_hole/sensor.py", line 69, in native_value
    return round(self.api.data[self.entity_description.key], 2)
KeyError: 'ads_blocked_today'
2022-07-27 18:04:03 WARNING (SyncWorker_6) [homeassistant.components.rpi_power.binary_sensor] Under-voltage was detected. Consider getting a uninterruptible power supply for your Raspberry Pi.
2022-07-27 18:08:03 ERROR (MainThread) [homeassistant] Error doing job: Task exception was never retrieved
Traceback (most recent call last):
  File "/usr/src/homeassistant/homeassistant/helpers/update_coordinator.py", line 151, in _handle_refresh_interval
    await self._async_refresh(log_failures=True, scheduled=True)
  File "/usr/src/homeassistant/homeassistant/helpers/update_coordinator.py", line 283, in _async_refresh
    self.async_update_listeners()
  File "/usr/src/homeassistant/homeassistant/helpers/update_coordinator.py", line 110, in async_update_listeners
    update_callback()
  File "/usr/src/homeassistant/homeassistant/helpers/update_coordinator.py", line 339, in _handle_coordinator_update
    self.async_write_ha_state()
  File "/usr/src/homeassistant/homeassistant/helpers/entity.py", line 532, in async_write_ha_state
    self._async_write_ha_state()
  File "/usr/src/homeassistant/homeassistant/helpers/entity.py", line 570, in _async_write_ha_state
    state = self._stringify_state(available)
  File "/usr/src/homeassistant/homeassistant/helpers/entity.py", line 538, in _stringify_state
    if (state := self.state) is None:
  File "/usr/src/homeassistant/homeassistant/components/sensor/__init__.py", line 388, in state
    value = self.native_value
  File "/usr/src/homeassistant/homeassistant/components/pi_hole/sensor.py", line 69, in native_value
    return round(self.api.data[self.entity_description.key], 2)
KeyError: 'ads_blocked_today'
2022-07-27 18:13:03 ERROR (MainThread) [homeassistant] Error doing job: Task exception was never retrieved
Traceback (most recent call last):
  File "/usr/src/homeassistant/homeassistant/helpers/update_coordinator.py", line 151, in _handle_refresh_interval
    await self._async_refresh(log_failures=True, scheduled=True)
  File "/usr/src/homeassistant/homeassistant/helpers/update_coordinator.py", line 283, in _async_refresh
    self.async_update_listeners()
  File "/usr/src/homeassistant/homeassistant/helpers/update_coordinator.py", line 110, in async_update_listeners
    update_callback()
  File "/usr/src/homeassistant/homeassistant/helpers/update_coordinator.py", line 339, in _handle_coordinator_update
    self.async_write_ha_state()
  File "/usr/src/homeassistant/homeassistant/helpers/entity.py", line 532, in async_write_ha_state
    self._async_write_ha_state()
  File "/usr/src/homeassistant/homeassistant/helpers/entity.py", line 570, in _async_write_ha_state
    state = self._stringify_state(available)
  File "/usr/src/homeassistant/homeassistant/helpers/entity.py", line 538, in _stringify_state
    if (state := self.state) is None:
  File "/usr/src/homeassistant/homeassistant/components/sensor/__init__.py", line 388, in state
    value = self.native_value
  File "/usr/src/homeassistant/homeassistant/components/pi_hole/sensor.py", line 69, in native_value
    return round(self.api.data[self.entity_description.key], 2)
KeyError: 'ads_blocked_today'
2022-07-27 18:18:03 ERROR (MainThread) [homeassistant] Error doing job: Task exception was never retrieved
Traceback (most recent call last):
  File "/usr/src/homeassistant/homeassistant/helpers/update_coordinator.py", line 151, in _handle_refresh_interval
    await self._async_refresh(log_failures=True, scheduled=True)
  File "/usr/src/homeassistant/homeassistant/helpers/update_coordinator.py", line 283, in _async_refresh
    self.async_update_listeners()
  File "/usr/src/homeassistant/homeassistant/helpers/update_coordinator.py", line 110, in async_update_listeners
    update_callback()
  File "/usr/src/homeassistant/homeassistant/helpers/update_coordinator.py", line 339, in _handle_coordinator_update
    self.async_write_ha_state()
  File "/usr/src/homeassistant/homeassistant/helpers/entity.py", line 532, in async_write_ha_state
    self._async_write_ha_state()
  File "/usr/src/homeassistant/homeassistant/helpers/entity.py", line 570, in _async_write_ha_state
    state = self._stringify_state(available)
  File "/usr/src/homeassistant/homeassistant/helpers/entity.py", line 538, in _stringify_state
    if (state := self.state) is None:
  File "/usr/src/homeassistant/homeassistant/components/sensor/__init__.py", line 388, in state
    value = self.native_value
  File "/usr/src/homeassistant/homeassistant/components/pi_hole/sensor.py", line 69, in native_value
    return round(self.api.data[self.entity_description.key], 2)
KeyError: 'ads_blocked_today'
2022-07-27 18:23:03 ERROR (MainThread) [homeassistant] Error doing job: Task exception was never retrieved
Traceback (most recent call last):
  File "/usr/src/homeassistant/homeassistant/helpers/update_coordinator.py", line 151, in _handle_refresh_interval
    await self._async_refresh(log_failures=True, scheduled=True)
  File "/usr/src/homeassistant/homeassistant/helpers/update_coordinator.py", line 283, in _async_refresh
    self.async_update_listeners()
  File "/usr/src/homeassistant/homeassistant/helpers/update_coordinator.py", line 110, in async_update_listeners
    update_callback()
  File "/usr/src/homeassistant/homeassistant/helpers/update_coordinator.py", line 339, in _handle_coordinator_update
    self.async_write_ha_state()
  File "/usr/src/homeassistant/homeassistant/helpers/entity.py", line 532, in async_write_ha_state
    self._async_write_ha_state()
  File "/usr/src/homeassistant/homeassistant/helpers/entity.py", line 570, in _async_write_ha_state
    state = self._stringify_state(available)
  File "/usr/src/homeassistant/homeassistant/helpers/entity.py", line 538, in _stringify_state
    if (state := self.state) is None:
  File "/usr/src/homeassistant/homeassistant/components/sensor/__init__.py", line 388, in state
    value = self.native_value
  File "/usr/src/homeassistant/homeassistant/components/pi_hole/sensor.py", line 69, in native_value
    return round(self.api.data[self.entity_description.key], 2)
KeyError: 'ads_blocked_today'
2022-07-27 18:28:03 ERROR (MainThread) [homeassistant] Error doing job: Task exception was never retrieved
Traceback (most recent call last):
  File "/usr/src/homeassistant/homeassistant/helpers/update_coordinator.py", line 151, in _handle_refresh_interval
    await self._async_refresh(log_failures=True, scheduled=True)
  File "/usr/src/homeassistant/homeassistant/helpers/update_coordinator.py", line 283, in _async_refresh
    self.async_update_listeners()
  File "/usr/src/homeassistant/homeassistant/helpers/update_coordinator.py", line 110, in async_update_listeners
    update_callback()
  File "/usr/src/homeassistant/homeassistant/helpers/update_coordinator.py", line 339, in _handle_coordinator_update
    self.async_write_ha_state()
  File "/usr/src/homeassistant/homeassistant/helpers/entity.py", line 532, in async_write_ha_state
    self._async_write_ha_state()
  File "/usr/src/homeassistant/homeassistant/helpers/entity.py", line 570, in _async_write_ha_state
    state = self._stringify_state(available)
  File "/usr/src/homeassistant/homeassistant/helpers/entity.py", line 538, in _stringify_state
    if (state := self.state) is None:
  File "/usr/src/homeassistant/homeassistant/components/sensor/__init__.py", line 388, in state
    value = self.native_value
  File "/usr/src/homeassistant/homeassistant/components/pi_hole/sensor.py", line 69, in native_value
    return round(self.api.data[self.entity_description.key], 2)
KeyError: 'ads_blocked_today'
2022-07-27 18:33:03 ERROR (MainThread) [homeassistant] Error doing job: Task exception was never retrieved
Traceback (most recent call last):
  File "/usr/src/homeassistant/homeassistant/helpers/update_coordinator.py", line 151, in _handle_refresh_interval
    await self._async_refresh(log_failures=True, scheduled=True)
  File "/usr/src/homeassistant/homeassistant/helpers/update_coordinator.py", line 283, in _async_refresh
    self.async_update_listeners()
  File "/usr/src/homeassistant/homeassistant/helpers/update_coordinator.py", line 110, in async_update_listeners
    update_callback()
  File "/usr/src/homeassistant/homeassistant/helpers/update_coordinator.py", line 339, in _handle_coordinator_update
    self.async_write_ha_state()
  File "/usr/src/homeassistant/homeassistant/helpers/entity.py", line 532, in async_write_ha_state
    self._async_write_ha_state()
  File "/usr/src/homeassistant/homeassistant/helpers/entity.py", line 570, in _async_write_ha_state
    state = self._stringify_state(available)
  File "/usr/src/homeassistant/homeassistant/helpers/entity.py", line 538, in _stringify_state
    if (state := self.state) is None:
  File "/usr/src/homeassistant/homeassistant/components/sensor/__init__.py", line 388, in state
    value = self.native_value
  File "/usr/src/homeassistant/homeassistant/components/pi_hole/sensor.py", line 69, in native_value
    return round(self.api.data[self.entity_description.key], 2)
KeyError: 'ads_blocked_today'
2022-07-27 18:38:03 ERROR (MainThread) [homeassistant] Error doing job: Task exception was never retrieved
Traceback (most recent call last):
  File "/usr/src/homeassistant/homeassistant/helpers/update_coordinator.py", line 151, in _handle_refresh_interval
    await self._async_refresh(log_failures=True, scheduled=True)
  File "/usr/src/homeassistant/homeassistant/helpers/update_coordinator.py", line 283, in _async_refresh
    self.async_update_listeners()
  File "/usr/src/homeassistant/homeassistant/helpers/update_coordinator.py", line 110, in async_update_listeners
    update_callback()
  File "/usr/src/homeassistant/homeassistant/helpers/update_coordinator.py", line 339, in _handle_coordinator_update
    self.async_write_ha_state()
  File "/usr/src/homeassistant/homeassistant/helpers/entity.py", line 532, in async_write_ha_state
    self._async_write_ha_state()
  File "/usr/src/homeassistant/homeassistant/helpers/entity.py", line 570, in _async_write_ha_state
    state = self._stringify_state(available)
  File "/usr/src/homeassistant/homeassistant/helpers/entity.py", line 538, in _stringify_state
    if (state := self.state) is None:
  File "/usr/src/homeassistant/homeassistant/components/sensor/__init__.py", line 388, in state
    value = self.native_value
  File "/usr/src/homeassistant/homeassistant/components/pi_hole/sensor.py", line 69, in native_value
    return round(self.api.data[self.entity_description.key], 2)
KeyError: 'ads_blocked_today'
2022-07-27 18:43:03 ERROR (MainThread) [homeassistant] Error doing job: Task exception was never retrieved
Traceback (most recent call last):
  File "/usr/src/homeassistant/homeassistant/helpers/update_coordinator.py", line 151, in _handle_refresh_interval
    await self._async_refresh(log_failures=True, scheduled=True)
  File "/usr/src/homeassistant/homeassistant/helpers/update_coordinator.py", line 283, in _async_refresh
    self.async_update_listeners()
  File "/usr/src/homeassistant/homeassistant/helpers/update_coordinator.py", line 110, in async_update_listeners
    update_callback()
  File "/usr/src/homeassistant/homeassistant/helpers/update_coordinator.py", line 339, in _handle_coordinator_update
    self.async_write_ha_state()
  File "/usr/src/homeassistant/homeassistant/helpers/entity.py", line 532, in async_write_ha_state
    self._async_write_ha_state()
  File "/usr/src/homeassistant/homeassistant/helpers/entity.py", line 570, in _async_write_ha_state
    state = self._stringify_state(available)
  File "/usr/src/homeassistant/homeassistant/helpers/entity.py", line 538, in _stringify_state
    if (state := self.state) is None:
  File "/usr/src/homeassistant/homeassistant/components/sensor/__init__.py", line 388, in state
    value = self.native_value
  File "/usr/src/homeassistant/homeassistant/components/pi_hole/sensor.py", line 69, in native_value
    return round(self.api.data[self.entity_description.key], 2)
KeyError: 'ads_blocked_today'
2022-07-27 18:48:03 ERROR (MainThread) [homeassistant] Error doing job: Task exception was never retrieved
Traceback (most recent call last):
  File "/usr/src/homeassistant/homeassistant/helpers/update_coordinator.py", line 151, in _handle_refresh_interval
    await self._async_refresh(log_failures=True, scheduled=True)
  File "/usr/src/homeassistant/homeassistant/helpers/update_coordinator.py", line 283, in _async_refresh
    self.async_update_listeners()
  File "/usr/src/homeassistant/homeassistant/helpers/update_coordinator.py", line 110, in async_update_listeners
    update_callback()
  File "/usr/src/homeassistant/homeassistant/helpers/update_coordinator.py", line 339, in _handle_coordinator_update
    self.async_write_ha_state()
  File "/usr/src/homeassistant/homeassistant/helpers/entity.py", line 532, in async_write_ha_state
    self._async_write_ha_state()
  File "/usr/src/homeassistant/homeassistant/helpers/entity.py", line 570, in _async_write_ha_state
    state = self._stringify_state(available)
  File "/usr/src/homeassistant/homeassistant/helpers/entity.py", line 538, in _stringify_state
    if (state := self.state) is None:
  File "/usr/src/homeassistant/homeassistant/components/sensor/__init__.py", line 388, in state
    value = self.native_value
  File "/usr/src/homeassistant/homeassistant/components/pi_hole/sensor.py", line 69, in native_value
    return round(self.api.data[self.entity_description.key], 2)
KeyError: 'ads_blocked_today'
2022-07-27 18:53:03 ERROR (MainThread) [homeassistant] Error doing job: Task exception was never retrieved
Traceback (most recent call last):
  File "/usr/src/homeassistant/homeassistant/helpers/update_coordinator.py", line 151, in _handle_refresh_interval
    await self._async_refresh(log_failures=True, scheduled=True)
  File "/usr/src/homeassistant/homeassistant/helpers/update_coordinator.py", line 283, in _async_refresh
    self.async_update_listeners()
  File "/usr/src/homeassistant/homeassistant/helpers/update_coordinator.py", line 110, in async_update_listeners
    update_callback()
  File "/usr/src/homeassistant/homeassistant/helpers/update_coordinator.py", line 339, in _handle_coordinator_update
    self.async_write_ha_state()
  File "/usr/src/homeassistant/homeassistant/helpers/entity.py", line 532, in async_write_ha_state
    self._async_write_ha_state()
  File "/usr/src/homeassistant/homeassistant/helpers/entity.py", line 570, in _async_write_ha_state
    state = self._stringify_state(available)
  File "/usr/src/homeassistant/homeassistant/helpers/entity.py", line 538, in _stringify_state
    if (state := self.state) is None:
  File "/usr/src/homeassistant/homeassistant/components/sensor/__init__.py", line 388, in state
    value = self.native_value
  File "/usr/src/homeassistant/homeassistant/components/pi_hole/sensor.py", line 69, in native_value
    return round(self.api.data[self.entity_description.key], 2)
KeyError: 'ads_blocked_today'
2022-07-27 18:58:03 ERROR (MainThread) [homeassistant] Error doing job: Task exception was never retrieved
Traceback (most recent call last):
  File "/usr/src/homeassistant/homeassistant/helpers/update_coordinator.py", line 151, in _handle_refresh_interval
    await self._async_refresh(log_failures=True, scheduled=True)
  File "/usr/src/homeassistant/homeassistant/helpers/update_coordinator.py", line 283, in _async_refresh
    self.async_update_listeners()
  File "/usr/src/homeassistant/homeassistant/helpers/update_coordinator.py", line 110, in async_update_listeners
    update_callback()
  File "/usr/src/homeassistant/homeassistant/helpers/update_coordinator.py", line 339, in _handle_coordinator_update
    self.async_write_ha_state()
  File "/usr/src/homeassistant/homeassistant/helpers/entity.py", line 532, in async_write_ha_state
    self._async_write_ha_state()
  File "/usr/src/homeassistant/homeassistant/helpers/entity.py", line 570, in _async_write_ha_state
    state = self._stringify_state(available)
  File "/usr/src/homeassistant/homeassistant/helpers/entity.py", line 538, in _stringify_state
    if (state := self.state) is None:
  File "/usr/src/homeassistant/homeassistant/components/sensor/__init__.py", line 388, in state
    value = self.native_value
  File "/usr/src/homeassistant/homeassistant/components/pi_hole/sensor.py", line 69, in native_value
    return round(self.api.data[self.entity_description.key], 2)
KeyError: 'ads_blocked_today'
2022-07-27 19:03:03 ERROR (MainThread) [homeassistant] Error doing job: Task exception was never retrieved
Traceback (most recent call last):
  File "/usr/src/homeassistant/homeassistant/helpers/update_coordinator.py", line 151, in _handle_refresh_interval
    await self._async_refresh(log_failures=True, scheduled=True)
  File "/usr/src/homeassistant/homeassistant/helpers/update_coordinator.py", line 283, in _async_refresh
    self.async_update_listeners()
  File "/usr/src/homeassistant/homeassistant/helpers/update_coordinator.py", line 110, in async_update_listeners
    update_callback()
  File "/usr/src/homeassistant/homeassistant/helpers/update_coordinator.py", line 339, in _handle_coordinator_update
    self.async_write_ha_state()
  File "/usr/src/homeassistant/homeassistant/helpers/entity.py", line 532, in async_write_ha_state
    self._async_write_ha_state()
  File "/usr/src/homeassistant/homeassistant/helpers/entity.py", line 570, in _async_write_ha_state
    state = self._stringify_state(available)
  File "/usr/src/homeassistant/homeassistant/helpers/entity.py", line 538, in _stringify_state
    if (state := self.state) is None:
  File "/usr/src/homeassistant/homeassistant/components/sensor/__init__.py", line 388, in state
    value = self.native_value
  File "/usr/src/homeassistant/homeassistant/components/pi_hole/sensor.py", line 69, in native_value
    return round(self.api.data[self.entity_description.key], 2)
KeyError: 'ads_blocked_today'
2022-07-27 19:08:03 ERROR (MainThread) [homeassistant] Error doing job: Task exception was never retrieved
Traceback (most recent call last):
  File "/usr/src/homeassistant/homeassistant/helpers/update_coordinator.py", line 151, in _handle_refresh_interval
    await self._async_refresh(log_failures=True, scheduled=True)
  File "/usr/src/homeassistant/homeassistant/helpers/update_coordinator.py", line 283, in _async_refresh
    self.async_update_listeners()
  File "/usr/src/homeassistant/homeassistant/helpers/update_coordinator.py", line 110, in async_update_listeners
    update_callback()
  File "/usr/src/homeassistant/homeassistant/helpers/update_coordinator.py", line 339, in _handle_coordinator_update
    self.async_write_ha_state()
  File "/usr/src/homeassistant/homeassistant/helpers/entity.py", line 532, in async_write_ha_state
    self._async_write_ha_state()
  File "/usr/src/homeassistant/homeassistant/helpers/entity.py", line 570, in _async_write_ha_state
    state = self._stringify_state(available)
  File "/usr/src/homeassistant/homeassistant/helpers/entity.py", line 538, in _stringify_state
    if (state := self.state) is None:
  File "/usr/src/homeassistant/homeassistant/components/sensor/__init__.py", line 388, in state
    value = self.native_value
  File "/usr/src/homeassistant/homeassistant/components/pi_hole/sensor.py", line 69, in native_value
    return round(self.api.data[self.entity_description.key], 2)
KeyError: 'ads_blocked_today'
2022-07-27 19:13:03 ERROR (MainThread) [homeassistant] Error doing job: Task exception was never retrieved
Traceback (most recent call last):
  File "/usr/src/homeassistant/homeassistant/helpers/update_coordinator.py", line 151, in _handle_refresh_interval
    await self._async_refresh(log_failures=True, scheduled=True)
  File "/usr/src/homeassistant/homeassistant/helpers/update_coordinator.py", line 283, in _async_refresh
    self.async_update_listeners()
  File "/usr/src/homeassistant/homeassistant/helpers/update_coordinator.py", line 110, in async_update_listeners
    update_callback()
  File "/usr/src/homeassistant/homeassistant/helpers/update_coordinator.py", line 339, in _handle_coordinator_update
    self.async_write_ha_state()
  File "/usr/src/homeassistant/homeassistant/helpers/entity.py", line 532, in async_write_ha_state
    self._async_write_ha_state()
  File "/usr/src/homeassistant/homeassistant/helpers/entity.py", line 570, in _async_write_ha_state
    state = self._stringify_state(available)
  File "/usr/src/homeassistant/homeassistant/helpers/entity.py", line 538, in _stringify_state
    if (state := self.state) is None:
  File "/usr/src/homeassistant/homeassistant/components/sensor/__init__.py", line 388, in state
    value = self.native_value
  File "/usr/src/homeassistant/homeassistant/components/pi_hole/sensor.py", line 69, in native_value
    return round(self.api.data[self.entity_description.key], 2)
KeyError: 'ads_blocked_today'
2022-07-27 19:17:33 WARNING (SyncWorker_0) [homeassistant.components.rpi_power.binary_sensor] Under-voltage was detected. Consider getting a uninterruptible power supply for your Raspberry Pi.
2022-07-27 19:18:03 ERROR (MainThread) [homeassistant] Error doing job: Task exception was never retrieved
Traceback (most recent call last):
  File "/usr/src/homeassistant/homeassistant/helpers/update_coordinator.py", line 151, in _handle_refresh_interval
    await self._async_refresh(log_failures=True, scheduled=True)
  File "/usr/src/homeassistant/homeassistant/helpers/update_coordinator.py", line 283, in _async_refresh
    self.async_update_listeners()
  File "/usr/src/homeassistant/homeassistant/helpers/update_coordinator.py", line 110, in async_update_listeners
    update_callback()
  File "/usr/src/homeassistant/homeassistant/helpers/update_coordinator.py", line 339, in _handle_coordinator_update
    self.async_write_ha_state()
  File "/usr/src/homeassistant/homeassistant/helpers/entity.py", line 532, in async_write_ha_state
    self._async_write_ha_state()
  File "/usr/src/homeassistant/homeassistant/helpers/entity.py", line 570, in _async_write_ha_state
    state = self._stringify_state(available)
  File "/usr/src/homeassistant/homeassistant/helpers/entity.py", line 538, in _stringify_state
    if (state := self.state) is None:
  File "/usr/src/homeassistant/homeassistant/components/sensor/__init__.py", line 388, in state
    value = self.native_value
  File "/usr/src/homeassistant/homeassistant/components/pi_hole/sensor.py", line 69, in native_value
    return round(self.api.data[self.entity_description.key], 2)
KeyError: 'ads_blocked_today'
2022-07-27 19:23:03 ERROR (MainThread) [homeassistant] Error doing job: Task exception was never retrieved
Traceback (most recent call last):
  File "/usr/src/homeassistant/homeassistant/helpers/update_coordinator.py", line 151, in _handle_refresh_interval
    await self._async_refresh(log_failures=True, scheduled=True)
  File "/usr/src/homeassistant/homeassistant/helpers/update_coordinator.py", line 283, in _async_refresh
    self.async_update_listeners()
  File "/usr/src/homeassistant/homeassistant/helpers/update_coordinator.py", line 110, in async_update_listeners
    update_callback()
  File "/usr/src/homeassistant/homeassistant/helpers/update_coordinator.py", line 339, in _handle_coordinator_update
    self.async_write_ha_state()
  File "/usr/src/homeassistant/homeassistant/helpers/entity.py", line 532, in async_write_ha_state
    self._async_write_ha_state()
  File "/usr/src/homeassistant/homeassistant/helpers/entity.py", line 570, in _async_write_ha_state
    state = self._stringify_state(available)
  File "/usr/src/homeassistant/homeassistant/helpers/entity.py", line 538, in _stringify_state
    if (state := self.state) is None:
  File "/usr/src/homeassistant/homeassistant/components/sensor/__init__.py", line 388, in state
    value = self.native_value
  File "/usr/src/homeassistant/homeassistant/components/pi_hole/sensor.py", line 69, in native_value
    return round(self.api.data[self.entity_description.key], 2)
KeyError: 'ads_blocked_today'
2022-07-27 19:28:03 ERROR (MainThread) [homeassistant] Error doing job: Task exception was never retrieved
Traceback (most recent call last):
  File "/usr/src/homeassistant/homeassistant/helpers/update_coordinator.py", line 151, in _handle_refresh_interval
    await self._async_refresh(log_failures=True, scheduled=True)
  File "/usr/src/homeassistant/homeassistant/helpers/update_coordinator.py", line 283, in _async_refresh
    self.async_update_listeners()
  File "/usr/src/homeassistant/homeassistant/helpers/update_coordinator.py", line 110, in async_update_listeners
    update_callback()
  File "/usr/src/homeassistant/homeassistant/helpers/update_coordinator.py", line 339, in _handle_coordinator_update
    self.async_write_ha_state()
  File "/usr/src/homeassistant/homeassistant/helpers/entity.py", line 532, in async_write_ha_state
    self._async_write_ha_state()
  File "/usr/src/homeassistant/homeassistant/helpers/entity.py", line 570, in _async_write_ha_state
    state = self._stringify_state(available)
  File "/usr/src/homeassistant/homeassistant/helpers/entity.py", line 538, in _stringify_state
    if (state := self.state) is None:
  File "/usr/src/homeassistant/homeassistant/components/sensor/__init__.py", line 388, in state
    value = self.native_value
  File "/usr/src/homeassistant/homeassistant/components/pi_hole/sensor.py", line 69, in native_value
    return round(self.api.data[self.entity_description.key], 2)
KeyError: 'ads_blocked_today'
2022-07-27 19:33:03 ERROR (MainThread) [homeassistant] Error doing job: Task exception was never retrieved
Traceback (most recent call last):
  File "/usr/src/homeassistant/homeassistant/helpers/update_coordinator.py", line 151, in _handle_refresh_interval
    await self._async_refresh(log_failures=True, scheduled=True)
  File "/usr/src/homeassistant/homeassistant/helpers/update_coordinator.py", line 283, in _async_refresh
    self.async_update_listeners()
  File "/usr/src/homeassistant/homeassistant/helpers/update_coordinator.py", line 110, in async_update_listeners
    update_callback()
  File "/usr/src/homeassistant/homeassistant/helpers/update_coordinator.py", line 339, in _handle_coordinator_update
    self.async_write_ha_state()
  File "/usr/src/homeassistant/homeassistant/helpers/entity.py", line 532, in async_write_ha_state
    self._async_write_ha_state()
  File "/usr/src/homeassistant/homeassistant/helpers/entity.py", line 570, in _async_write_ha_state
    state = self._stringify_state(available)
  File "/usr/src/homeassistant/homeassistant/helpers/entity.py", line 538, in _stringify_state
    if (state := self.state) is None:
  File "/usr/src/homeassistant/homeassistant/components/sensor/__init__.py", line 388, in state
    value = self.native_value
  File "/usr/src/homeassistant/homeassistant/components/pi_hole/sensor.py", line 69, in native_value
    return round(self.api.data[self.entity_description.key], 2)
KeyError: 'ads_blocked_today'
2022-07-27 19:38:03 ERROR (MainThread) [homeassistant] Error doing job: Task exception was never retrieved
Traceback (most recent call last):
  File "/usr/src/homeassistant/homeassistant/helpers/update_coordinator.py", line 151, in _handle_refresh_interval
    await self._async_refresh(log_failures=True, scheduled=True)
  File "/usr/src/homeassistant/homeassistant/helpers/update_coordinator.py", line 283, in _async_refresh
    self.async_update_listeners()
  File "/usr/src/homeassistant/homeassistant/helpers/update_coordinator.py", line 110, in async_update_listeners
    update_callback()
  File "/usr/src/homeassistant/homeassistant/helpers/update_coordinator.py", line 339, in _handle_coordinator_update
    self.async_write_ha_state()
  File "/usr/src/homeassistant/homeassistant/helpers/entity.py", line 532, in async_write_ha_state
    self._async_write_ha_state()
  File "/usr/src/homeassistant/homeassistant/helpers/entity.py", line 570, in _async_write_ha_state
    state = self._stringify_state(available)
  File "/usr/src/homeassistant/homeassistant/helpers/entity.py", line 538, in _stringify_state
    if (state := self.state) is None:
  File "/usr/src/homeassistant/homeassistant/components/sensor/__init__.py", line 388, in state
    value = self.native_value
  File "/usr/src/homeassistant/homeassistant/components/pi_hole/sensor.py", line 69, in native_value
    return round(self.api.data[self.entity_description.key], 2)
KeyError: 'ads_blocked_today'
2022-07-27 19:43:03 ERROR (MainThread) [homeassistant] Error doing job: Task exception was never retrieved
Traceback (most recent call last):
  File "/usr/src/homeassistant/homeassistant/helpers/update_coordinator.py", line 151, in _handle_refresh_interval
    await self._async_refresh(log_failures=True, scheduled=True)
  File "/usr/src/homeassistant/homeassistant/helpers/update_coordinator.py", line 283, in _async_refresh
    self.async_update_listeners()
  File "/usr/src/homeassistant/homeassistant/helpers/update_coordinator.py", line 110, in async_update_listeners
    update_callback()
  File "/usr/src/homeassistant/homeassistant/helpers/update_coordinator.py", line 339, in _handle_coordinator_update
    self.async_write_ha_state()
  File "/usr/src/homeassistant/homeassistant/helpers/entity.py", line 532, in async_write_ha_state
    self._async_write_ha_state()
  File "/usr/src/homeassistant/homeassistant/helpers/entity.py", line 570, in _async_write_ha_state
    state = self._stringify_state(available)
  File "/usr/src/homeassistant/homeassistant/helpers/entity.py", line 538, in _stringify_state
    if (state := self.state) is None:
  File "/usr/src/homeassistant/homeassistant/components/sensor/__init__.py", line 388, in state
    value = self.native_value
  File "/usr/src/homeassistant/homeassistant/components/pi_hole/sensor.py", line 69, in native_value
    return round(self.api.data[self.entity_description.key], 2)
KeyError: 'ads_blocked_today'
2022-07-27 19:48:03 ERROR (MainThread) [homeassistant] Error doing job: Task exception was never retrieved
Traceback (most recent call last):
  File "/usr/src/homeassistant/homeassistant/helpers/update_coordinator.py", line 151, in _handle_refresh_interval
    await self._async_refresh(log_failures=True, scheduled=True)
  File "/usr/src/homeassistant/homeassistant/helpers/update_coordinator.py", line 283, in _async_refresh
    self.async_update_listeners()
  File "/usr/src/homeassistant/homeassistant/helpers/update_coordinator.py", line 110, in async_update_listeners
    update_callback()
  File "/usr/src/homeassistant/homeassistant/helpers/update_coordinator.py", line 339, in _handle_coordinator_update
    self.async_write_ha_state()
  File "/usr/src/homeassistant/homeassistant/helpers/entity.py", line 532, in async_write_ha_state
    self._async_write_ha_state()
  File "/usr/src/homeassistant/homeassistant/helpers/entity.py", line 570, in _async_write_ha_state
    state = self._stringify_state(available)
  File "/usr/src/homeassistant/homeassistant/helpers/entity.py", line 538, in _stringify_state
    if (state := self.state) is None:
  File "/usr/src/homeassistant/homeassistant/components/sensor/__init__.py", line 388, in state
    value = self.native_value
  File "/usr/src/homeassistant/homeassistant/components/pi_hole/sensor.py", line 69, in native_value
    return round(self.api.data[self.entity_description.key], 2)
KeyError: 'ads_blocked_today'
2022-07-27 19:53:03 ERROR (MainThread) [homeassistant] Error doing job: Task exception was never retrieved
Traceback (most recent call last):
  File "/usr/src/homeassistant/homeassistant/helpers/update_coordinator.py", line 151, in _handle_refresh_interval
    await self._async_refresh(log_failures=True, scheduled=True)
  File "/usr/src/homeassistant/homeassistant/helpers/update_coordinator.py", line 283, in _async_refresh
    self.async_update_listeners()
  File "/usr/src/homeassistant/homeassistant/helpers/update_coordinator.py", line 110, in async_update_listeners
    update_callback()
  File "/usr/src/homeassistant/homeassistant/helpers/update_coordinator.py", line 339, in _handle_coordinator_update
    self.async_write_ha_state()
  File "/usr/src/homeassistant/homeassistant/helpers/entity.py", line 532, in async_write_ha_state
    self._async_write_ha_state()
  File "/usr/src/homeassistant/homeassistant/helpers/entity.py", line 570, in _async_write_ha_state
    state = self._stringify_state(available)
  File "/usr/src/homeassistant/homeassistant/helpers/entity.py", line 538, in _stringify_state
    if (state := self.state) is None:
  File "/usr/src/homeassistant/homeassistant/components/sensor/__init__.py", line 388, in state
    value = self.native_value
  File "/usr/src/homeassistant/homeassistant/components/pi_hole/sensor.py", line 69, in native_value
    return round(self.api.data[self.entity_description.key], 2)
KeyError: 'ads_blocked_today'
2022-07-27 19:58:03 ERROR (MainThread) [homeassistant] Error doing job: Task exception was never retrieved
Traceback (most recent call last):
  File "/usr/src/homeassistant/homeassistant/helpers/update_coordinator.py", line 151, in _handle_refresh_interval
    await self._async_refresh(log_failures=True, scheduled=True)
  File "/usr/src/homeassistant/homeassistant/helpers/update_coordinator.py", line 283, in _async_refresh
    self.async_update_listeners()
  File "/usr/src/homeassistant/homeassistant/helpers/update_coordinator.py", line 110, in async_update_listeners
    update_callback()
  File "/usr/src/homeassistant/homeassistant/helpers/update_coordinator.py", line 339, in _handle_coordinator_update
    self.async_write_ha_state()
  File "/usr/src/homeassistant/homeassistant/helpers/entity.py", line 532, in async_write_ha_state
    self._async_write_ha_state()
  File "/usr/src/homeassistant/homeassistant/helpers/entity.py", line 570, in _async_write_ha_state
    state = self._stringify_state(available)
  File "/usr/src/homeassistant/homeassistant/helpers/entity.py", line 538, in _stringify_state
    if (state := self.state) is None:
  File "/usr/src/homeassistant/homeassistant/components/sensor/__init__.py", line 388, in state
    value = self.native_value
  File "/usr/src/homeassistant/homeassistant/components/pi_hole/sensor.py", line 69, in native_value
    return round(self.api.data[self.entity_description.key], 2)
KeyError: 'ads_blocked_today'
2022-07-27 20:03:03 ERROR (MainThread) [homeassistant] Error doing job: Task exception was never retrieved
Traceback (most recent call last):
  File "/usr/src/homeassistant/homeassistant/helpers/update_coordinator.py", line 151, in _handle_refresh_interval
    await self._async_refresh(log_failures=True, scheduled=True)
  File "/usr/src/homeassistant/homeassistant/helpers/update_coordinator.py", line 283, in _async_refresh
    self.async_update_listeners()
  File "/usr/src/homeassistant/homeassistant/helpers/update_coordinator.py", line 110, in async_update_listeners
    update_callback()
  File "/usr/src/homeassistant/homeassistant/helpers/update_coordinator.py", line 339, in _handle_coordinator_update
    self.async_write_ha_state()
  File "/usr/src/homeassistant/homeassistant/helpers/entity.py", line 532, in async_write_ha_state
    self._async_write_ha_state()
  File "/usr/src/homeassistant/homeassistant/helpers/entity.py", line 570, in _async_write_ha_state
    state = self._stringify_state(available)
  File "/usr/src/homeassistant/homeassistant/helpers/entity.py", line 538, in _stringify_state
    if (state := self.state) is None:
  File "/usr/src/homeassistant/homeassistant/components/sensor/__init__.py", line 388, in state
    value = self.native_value
  File "/usr/src/homeassistant/homeassistant/components/pi_hole/sensor.py", line 69, in native_value
    return round(self.api.data[self.entity_description.key], 2)
KeyError: 'ads_blocked_today'
2022-07-27 20:08:03 ERROR (MainThread) [homeassistant] Error doing job: Task exception was never retrieved
Traceback (most recent call last):
  File "/usr/src/homeassistant/homeassistant/helpers/update_coordinator.py", line 151, in _handle_refresh_interval
    await self._async_refresh(log_failures=True, scheduled=True)
  File "/usr/src/homeassistant/homeassistant/helpers/update_coordinator.py", line 283, in _async_refresh
    self.async_update_listeners()
  File "/usr/src/homeassistant/homeassistant/helpers/update_coordinator.py", line 110, in async_update_listeners
    update_callback()
  File "/usr/src/homeassistant/homeassistant/helpers/update_coordinator.py", line 339, in _handle_coordinator_update
    self.async_write_ha_state()
  File "/usr/src/homeassistant/homeassistant/helpers/entity.py", line 532, in async_write_ha_state
    self._async_write_ha_state()
  File "/usr/src/homeassistant/homeassistant/helpers/entity.py", line 570, in _async_write_ha_state
    state = self._stringify_state(available)
  File "/usr/src/homeassistant/homeassistant/helpers/entity.py", line 538, in _stringify_state
    if (state := self.state) is None:
  File "/usr/src/homeassistant/homeassistant/components/sensor/__init__.py", line 388, in state
    value = self.native_value
  File "/usr/src/homeassistant/homeassistant/components/pi_hole/sensor.py", line 69, in native_value
    return round(self.api.data[self.entity_description.key], 2)
KeyError: 'ads_blocked_today'
2022-07-27 20:11:04 WARNING (SyncWorker_3) [homeassistant.components.rpi_power.binary_sensor] Under-voltage was detected. Consider getting a uninterruptible power supply for your Raspberry Pi.
2022-07-27 20:13:03 ERROR (MainThread) [homeassistant] Error doing job: Task exception was never retrieved
Traceback (most recent call last):
  File "/usr/src/homeassistant/homeassistant/helpers/update_coordinator.py", line 151, in _handle_refresh_interval
    await self._async_refresh(log_failures=True, scheduled=True)
  File "/usr/src/homeassistant/homeassistant/helpers/update_coordinator.py", line 283, in _async_refresh
    self.async_update_listeners()
  File "/usr/src/homeassistant/homeassistant/helpers/update_coordinator.py", line 110, in async_update_listeners
    update_callback()
  File "/usr/src/homeassistant/homeassistant/helpers/update_coordinator.py", line 339, in _handle_coordinator_update
    self.async_write_ha_state()
  File "/usr/src/homeassistant/homeassistant/helpers/entity.py", line 532, in async_write_ha_state
    self._async_write_ha_state()
  File "/usr/src/homeassistant/homeassistant/helpers/entity.py", line 570, in _async_write_ha_state
    state = self._stringify_state(available)
  File "/usr/src/homeassistant/homeassistant/helpers/entity.py", line 538, in _stringify_state
    if (state := self.state) is None:
  File "/usr/src/homeassistant/homeassistant/components/sensor/__init__.py", line 388, in state
    value = self.native_value
  File "/usr/src/homeassistant/homeassistant/components/pi_hole/sensor.py", line 69, in native_value
    return round(self.api.data[self.entity_description.key], 2)
KeyError: 'ads_blocked_today'
2022-07-27 20:18:03 ERROR (MainThread) [homeassistant] Error doing job: Task exception was never retrieved
Traceback (most recent call last):
  File "/usr/src/homeassistant/homeassistant/helpers/update_coordinator.py", line 151, in _handle_refresh_interval
    await self._async_refresh(log_failures=True, scheduled=True)
  File "/usr/src/homeassistant/homeassistant/helpers/update_coordinator.py", line 283, in _async_refresh
    self.async_update_listeners()
  File "/usr/src/homeassistant/homeassistant/helpers/update_coordinator.py", line 110, in async_update_listeners
    update_callback()
  File "/usr/src/homeassistant/homeassistant/helpers/update_coordinator.py", line 339, in _handle_coordinator_update
    self.async_write_ha_state()
  File "/usr/src/homeassistant/homeassistant/helpers/entity.py", line 532, in async_write_ha_state
    self._async_write_ha_state()
  File "/usr/src/homeassistant/homeassistant/helpers/entity.py", line 570, in _async_write_ha_state
    state = self._stringify_state(available)
  File "/usr/src/homeassistant/homeassistant/helpers/entity.py", line 538, in _stringify_state
    if (state := self.state) is None:
  File "/usr/src/homeassistant/homeassistant/components/sensor/__init__.py", line 388, in state
    value = self.native_value
  File "/usr/src/homeassistant/homeassistant/components/pi_hole/sensor.py", line 69, in native_value
    return round(self.api.data[self.entity_description.key], 2)
KeyError: 'ads_blocked_today'
2022-07-27 20:23:03 ERROR (MainThread) [homeassistant] Error doing job: Task exception was never retrieved
Traceback (most recent call last):
  File "/usr/src/homeassistant/homeassistant/helpers/update_coordinator.py", line 151, in _handle_refresh_interval
    await self._async_refresh(log_failures=True, scheduled=True)
  File "/usr/src/homeassistant/homeassistant/helpers/update_coordinator.py", line 283, in _async_refresh
    self.async_update_listeners()
  File "/usr/src/homeassistant/homeassistant/helpers/update_coordinator.py", line 110, in async_update_listeners
    update_callback()
  File "/usr/src/homeassistant/homeassistant/helpers/update_coordinator.py", line 339, in _handle_coordinator_update
    self.async_write_ha_state()
  File "/usr/src/homeassistant/homeassistant/helpers/entity.py", line 532, in async_write_ha_state
    self._async_write_ha_state()
  File "/usr/src/homeassistant/homeassistant/helpers/entity.py", line 570, in _async_write_ha_state
    state = self._stringify_state(available)
  File "/usr/src/homeassistant/homeassistant/helpers/entity.py", line 538, in _stringify_state
    if (state := self.state) is None:
  File "/usr/src/homeassistant/homeassistant/components/sensor/__init__.py", line 388, in state
    value = self.native_value
  File "/usr/src/homeassistant/homeassistant/components/pi_hole/sensor.py", line 69, in native_value
    return round(self.api.data[self.entity_description.key], 2)
KeyError: 'ads_blocked_today'
2022-07-27 20:28:03 ERROR (MainThread) [homeassistant] Error doing job: Task exception was never retrieved
Traceback (most recent call last):
  File "/usr/src/homeassistant/homeassistant/helpers/update_coordinator.py", line 151, in _handle_refresh_interval
    await self._async_refresh(log_failures=True, scheduled=True)
  File "/usr/src/homeassistant/homeassistant/helpers/update_coordinator.py", line 283, in _async_refresh
    self.async_update_listeners()
  File "/usr/src/homeassistant/homeassistant/helpers/update_coordinator.py", line 110, in async_update_listeners
    update_callback()
  File "/usr/src/homeassistant/homeassistant/helpers/update_coordinator.py", line 339, in _handle_coordinator_update
    self.async_write_ha_state()
  File "/usr/src/homeassistant/homeassistant/helpers/entity.py", line 532, in async_write_ha_state
    self._async_write_ha_state()
  File "/usr/src/homeassistant/homeassistant/helpers/entity.py", line 570, in _async_write_ha_state
    state = self._stringify_state(available)
  File "/usr/src/homeassistant/homeassistant/helpers/entity.py", line 538, in _stringify_state
    if (state := self.state) is None:
  File "/usr/src/homeassistant/homeassistant/components/sensor/__init__.py", line 388, in state
    value = self.native_value
  File "/usr/src/homeassistant/homeassistant/components/pi_hole/sensor.py", line 69, in native_value
    return round(self.api.data[self.entity_description.key], 2)
KeyError: 'ads_blocked_today'
2022-07-27 20:33:03 ERROR (MainThread) [homeassistant] Error doing job: Task exception was never retrieved
Traceback (most recent call last):
  File "/usr/src/homeassistant/homeassistant/helpers/update_coordinator.py", line 151, in _handle_refresh_interval
    await self._async_refresh(log_failures=True, scheduled=True)
  File "/usr/src/homeassistant/homeassistant/helpers/update_coordinator.py", line 283, in _async_refresh
    self.async_update_listeners()
  File "/usr/src/homeassistant/homeassistant/helpers/update_coordinator.py", line 110, in async_update_listeners
    update_callback()
  File "/usr/src/homeassistant/homeassistant/helpers/update_coordinator.py", line 339, in _handle_coordinator_update
    self.async_write_ha_state()
  File "/usr/src/homeassistant/homeassistant/helpers/entity.py", line 532, in async_write_ha_state
    self._async_write_ha_state()
  File "/usr/src/homeassistant/homeassistant/helpers/entity.py", line 570, in _async_write_ha_state
    state = self._stringify_state(available)
  File "/usr/src/homeassistant/homeassistant/helpers/entity.py", line 538, in _stringify_state
    if (state := self.state) is None:
  File "/usr/src/homeassistant/homeassistant/components/sensor/__init__.py", line 388, in state
    value = self.native_value
  File "/usr/src/homeassistant/homeassistant/components/pi_hole/sensor.py", line 69, in native_value
    return round(self.api.data[self.entity_description.key], 2)
KeyError: 'ads_blocked_today'
2022-07-27 20:38:03 ERROR (MainThread) [homeassistant] Error doing job: Task exception was never retrieved
Traceback (most recent call last):
  File "/usr/src/homeassistant/homeassistant/helpers/update_coordinator.py", line 151, in _handle_refresh_interval
    await self._async_refresh(log_failures=True, scheduled=True)
  File "/usr/src/homeassistant/homeassistant/helpers/update_coordinator.py", line 283, in _async_refresh
    self.async_update_listeners()
  File "/usr/src/homeassistant/homeassistant/helpers/update_coordinator.py", line 110, in async_update_listeners
    update_callback()
  File "/usr/src/homeassistant/homeassistant/helpers/update_coordinator.py", line 339, in _handle_coordinator_update
    self.async_write_ha_state()
  File "/usr/src/homeassistant/homeassistant/helpers/entity.py", line 532, in async_write_ha_state
    self._async_write_ha_state()
  File "/usr/src/homeassistant/homeassistant/helpers/entity.py", line 570, in _async_write_ha_state
    state = self._stringify_state(available)
  File "/usr/src/homeassistant/homeassistant/helpers/entity.py", line 538, in _stringify_state
    if (state := self.state) is None:
  File "/usr/src/homeassistant/homeassistant/components/sensor/__init__.py", line 388, in state
    value = self.native_value
  File "/usr/src/homeassistant/homeassistant/components/pi_hole/sensor.py", line 69, in native_value
    return round(self.api.data[self.entity_description.key], 2)
KeyError: 'ads_blocked_today'
2022-07-27 20:43:03 ERROR (MainThread) [homeassistant] Error doing job: Task exception was never retrieved
Traceback (most recent call last):
  File "/usr/src/homeassistant/homeassistant/helpers/update_coordinator.py", line 151, in _handle_refresh_interval
    await self._async_refresh(log_failures=True, scheduled=True)
  File "/usr/src/homeassistant/homeassistant/helpers/update_coordinator.py", line 283, in _async_refresh
    self.async_update_listeners()
  File "/usr/src/homeassistant/homeassistant/helpers/update_coordinator.py", line 110, in async_update_listeners
    update_callback()
  File "/usr/src/homeassistant/homeassistant/helpers/update_coordinator.py", line 339, in _handle_coordinator_update
    self.async_write_ha_state()
  File "/usr/src/homeassistant/homeassistant/helpers/entity.py", line 532, in async_write_ha_state
    self._async_write_ha_state()
  File "/usr/src/homeassistant/homeassistant/helpers/entity.py", line 570, in _async_write_ha_state
    state = self._stringify_state(available)
  File "/usr/src/homeassistant/homeassistant/helpers/entity.py", line 538, in _stringify_state
    if (state := self.state) is None:
  File "/usr/src/homeassistant/homeassistant/components/sensor/__init__.py", line 388, in state
    value = self.native_value
  File "/usr/src/homeassistant/homeassistant/components/pi_hole/sensor.py", line 69, in native_value
    return round(self.api.data[self.entity_description.key], 2)
KeyError: 'ads_blocked_today'
2022-07-27 20:48:03 ERROR (MainThread) [homeassistant] Error doing job: Task exception was never retrieved
Traceback (most recent call last):
  File "/usr/src/homeassistant/homeassistant/helpers/update_coordinator.py", line 151, in _handle_refresh_interval
    await self._async_refresh(log_failures=True, scheduled=True)
  File "/usr/src/homeassistant/homeassistant/helpers/update_coordinator.py", line 283, in _async_refresh
    self.async_update_listeners()
  File "/usr/src/homeassistant/homeassistant/helpers/update_coordinator.py", line 110, in async_update_listeners
    update_callback()
  File "/usr/src/homeassistant/homeassistant/helpers/update_coordinator.py", line 339, in _handle_coordinator_update
    self.async_write_ha_state()
  File "/usr/src/homeassistant/homeassistant/helpers/entity.py", line 532, in async_write_ha_state
    self._async_write_ha_state()
  File "/usr/src/homeassistant/homeassistant/helpers/entity.py", line 570, in _async_write_ha_state
    state = self._stringify_state(available)
  File "/usr/src/homeassistant/homeassistant/helpers/entity.py", line 538, in _stringify_state
    if (state := self.state) is None:
  File "/usr/src/homeassistant/homeassistant/components/sensor/__init__.py", line 388, in state
    value = self.native_value
  File "/usr/src/homeassistant/homeassistant/components/pi_hole/sensor.py", line 69, in native_value
    return round(self.api.data[self.entity_description.key], 2)
KeyError: 'ads_blocked_today'
2022-07-27 20:53:03 ERROR (MainThread) [homeassistant] Error doing job: Task exception was never retrieved
Traceback (most recent call last):
  File "/usr/src/homeassistant/homeassistant/helpers/update_coordinator.py", line 151, in _handle_refresh_interval
    await self._async_refresh(log_failures=True, scheduled=True)
  File "/usr/src/homeassistant/homeassistant/helpers/update_coordinator.py", line 283, in _async_refresh
    self.async_update_listeners()
  File "/usr/src/homeassistant/homeassistant/helpers/update_coordinator.py", line 110, in async_update_listeners
    update_callback()
  File "/usr/src/homeassistant/homeassistant/helpers/update_coordinator.py", line 339, in _handle_coordinator_update
    self.async_write_ha_state()
  File "/usr/src/homeassistant/homeassistant/helpers/entity.py", line 532, in async_write_ha_state
    self._async_write_ha_state()
  File "/usr/src/homeassistant/homeassistant/helpers/entity.py", line 570, in _async_write_ha_state
    state = self._stringify_state(available)
  File "/usr/src/homeassistant/homeassistant/helpers/entity.py", line 538, in _stringify_state
    if (state := self.state) is None:
  File "/usr/src/homeassistant/homeassistant/components/sensor/__init__.py", line 388, in state
    value = self.native_value
  File "/usr/src/homeassistant/homeassistant/components/pi_hole/sensor.py", line 69, in native_value
    return round(self.api.data[self.entity_description.key], 2)
KeyError: 'ads_blocked_today'
2022-07-27 20:58:03 ERROR (MainThread) [homeassistant] Error doing job: Task exception was never retrieved
Traceback (most recent call last):
  File "/usr/src/homeassistant/homeassistant/helpers/update_coordinator.py", line 151, in _handle_refresh_interval
    await self._async_refresh(log_failures=True, scheduled=True)
  File "/usr/src/homeassistant/homeassistant/helpers/update_coordinator.py", line 283, in _async_refresh
    self.async_update_listeners()
  File "/usr/src/homeassistant/homeassistant/helpers/update_coordinator.py", line 110, in async_update_listeners
    update_callback()
  File "/usr/src/homeassistant/homeassistant/helpers/update_coordinator.py", line 339, in _handle_coordinator_update
    self.async_write_ha_state()
  File "/usr/src/homeassistant/homeassistant/helpers/entity.py", line 532, in async_write_ha_state
    self._async_write_ha_state()
  File "/usr/src/homeassistant/homeassistant/helpers/entity.py", line 570, in _async_write_ha_state
    state = self._stringify_state(available)
  File "/usr/src/homeassistant/homeassistant/helpers/entity.py", line 538, in _stringify_state
    if (state := self.state) is None:
  File "/usr/src/homeassistant/homeassistant/components/sensor/__init__.py", line 388, in state
    value = self.native_value
  File "/usr/src/homeassistant/homeassistant/components/pi_hole/sensor.py", line 69, in native_value
    return round(self.api.data[self.entity_description.key], 2)
KeyError: 'ads_blocked_today'
2022-07-27 21:03:03 ERROR (MainThread) [homeassistant] Error doing job: Task exception was never retrieved
Traceback (most recent call last):
  File "/usr/src/homeassistant/homeassistant/helpers/update_coordinator.py", line 151, in _handle_refresh_interval
    await self._async_refresh(log_failures=True, scheduled=True)
  File "/usr/src/homeassistant/homeassistant/helpers/update_coordinator.py", line 283, in _async_refresh
    self.async_update_listeners()
  File "/usr/src/homeassistant/homeassistant/helpers/update_coordinator.py", line 110, in async_update_listeners
    update_callback()
  File "/usr/src/homeassistant/homeassistant/helpers/update_coordinator.py", line 339, in _handle_coordinator_update
    self.async_write_ha_state()
  File "/usr/src/homeassistant/homeassistant/helpers/entity.py", line 532, in async_write_ha_state
    self._async_write_ha_state()
  File "/usr/src/homeassistant/homeassistant/helpers/entity.py", line 570, in _async_write_ha_state
    state = self._stringify_state(available)
  File "/usr/src/homeassistant/homeassistant/helpers/entity.py", line 538, in _stringify_state
    if (state := self.state) is None:
  File "/usr/src/homeassistant/homeassistant/components/sensor/__init__.py", line 388, in state
    value = self.native_value
  File "/usr/src/homeassistant/homeassistant/components/pi_hole/sensor.py", line 69, in native_value
    return round(self.api.data[self.entity_description.key], 2)
KeyError: 'ads_blocked_today'
2022-07-27 21:08:03 ERROR (MainThread) [homeassistant] Error doing job: Task exception was never retrieved
Traceback (most recent call last):
  File "/usr/src/homeassistant/homeassistant/helpers/update_coordinator.py", line 151, in _handle_refresh_interval
    await self._async_refresh(log_failures=True, scheduled=True)
  File "/usr/src/homeassistant/homeassistant/helpers/update_coordinator.py", line 283, in _async_refresh
    self.async_update_listeners()
  File "/usr/src/homeassistant/homeassistant/helpers/update_coordinator.py", line 110, in async_update_listeners
    update_callback()
  File "/usr/src/homeassistant/homeassistant/helpers/update_coordinator.py", line 339, in _handle_coordinator_update
    self.async_write_ha_state()
  File "/usr/src/homeassistant/homeassistant/helpers/entity.py", line 532, in async_write_ha_state
    self._async_write_ha_state()
  File "/usr/src/homeassistant/homeassistant/helpers/entity.py", line 570, in _async_write_ha_state
    state = self._stringify_state(available)
  File "/usr/src/homeassistant/homeassistant/helpers/entity.py", line 538, in _stringify_state
    if (state := self.state) is None:
  File "/usr/src/homeassistant/homeassistant/components/sensor/__init__.py", line 388, in state
    value = self.native_value
  File "/usr/src/homeassistant/homeassistant/components/pi_hole/sensor.py", line 69, in native_value
    return round(self.api.data[self.entity_description.key], 2)
KeyError: 'ads_blocked_today'
2022-07-27 21:13:03 ERROR (MainThread) [homeassistant] Error doing job: Task exception was never retrieved
Traceback (most recent call last):
  File "/usr/src/homeassistant/homeassistant/helpers/update_coordinator.py", line 151, in _handle_refresh_interval
    await self._async_refresh(log_failures=True, scheduled=True)
  File "/usr/src/homeassistant/homeassistant/helpers/update_coordinator.py", line 283, in _async_refresh
    self.async_update_listeners()
  File "/usr/src/homeassistant/homeassistant/helpers/update_coordinator.py", line 110, in async_update_listeners
    update_callback()
  File "/usr/src/homeassistant/homeassistant/helpers/update_coordinator.py", line 339, in _handle_coordinator_update
    self.async_write_ha_state()
  File "/usr/src/homeassistant/homeassistant/helpers/entity.py", line 532, in async_write_ha_state
    self._async_write_ha_state()
  File "/usr/src/homeassistant/homeassistant/helpers/entity.py", line 570, in _async_write_ha_state
    state = self._stringify_state(available)
  File "/usr/src/homeassistant/homeassistant/helpers/entity.py", line 538, in _stringify_state
    if (state := self.state) is None:
  File "/usr/src/homeassistant/homeassistant/components/sensor/__init__.py", line 388, in state
    value = self.native_value
  File "/usr/src/homeassistant/homeassistant/components/pi_hole/sensor.py", line 69, in native_value
    return round(self.api.data[self.entity_description.key], 2)
KeyError: 'ads_blocked_today'
2022-07-27 21:18:03 ERROR (MainThread) [homeassistant] Error doing job: Task exception was never retrieved
Traceback (most recent call last):
  File "/usr/src/homeassistant/homeassistant/helpers/update_coordinator.py", line 151, in _handle_refresh_interval
    await self._async_refresh(log_failures=True, scheduled=True)
  File "/usr/src/homeassistant/homeassistant/helpers/update_coordinator.py", line 283, in _async_refresh
    self.async_update_listeners()
  File "/usr/src/homeassistant/homeassistant/helpers/update_coordinator.py", line 110, in async_update_listeners
    update_callback()
  File "/usr/src/homeassistant/homeassistant/helpers/update_coordinator.py", line 339, in _handle_coordinator_update
    self.async_write_ha_state()
  File "/usr/src/homeassistant/homeassistant/helpers/entity.py", line 532, in async_write_ha_state
    self._async_write_ha_state()
  File "/usr/src/homeassistant/homeassistant/helpers/entity.py", line 570, in _async_write_ha_state
    state = self._stringify_state(available)
  File "/usr/src/homeassistant/homeassistant/helpers/entity.py", line 538, in _stringify_state
    if (state := self.state) is None:
  File "/usr/src/homeassistant/homeassistant/components/sensor/__init__.py", line 388, in state
    value = self.native_value
  File "/usr/src/homeassistant/homeassistant/components/pi_hole/sensor.py", line 69, in native_value
    return round(self.api.data[self.entity_description.key], 2)
KeyError: 'ads_blocked_today'
2022-07-27 21:23:03 ERROR (MainThread) [homeassistant] Error doing job: Task exception was never retrieved
Traceback (most recent call last):
  File "/usr/src/homeassistant/homeassistant/helpers/update_coordinator.py", line 151, in _handle_refresh_interval
    await self._async_refresh(log_failures=True, scheduled=True)
  File "/usr/src/homeassistant/homeassistant/helpers/update_coordinator.py", line 283, in _async_refresh
    self.async_update_listeners()
  File "/usr/src/homeassistant/homeassistant/helpers/update_coordinator.py", line 110, in async_update_listeners
    update_callback()
  File "/usr/src/homeassistant/homeassistant/helpers/update_coordinator.py", line 339, in _handle_coordinator_update
    self.async_write_ha_state()
  File "/usr/src/homeassistant/homeassistant/helpers/entity.py", line 532, in async_write_ha_state
    self._async_write_ha_state()
  File "/usr/src/homeassistant/homeassistant/helpers/entity.py", line 570, in _async_write_ha_state
    state = self._stringify_state(available)
  File "/usr/src/homeassistant/homeassistant/helpers/entity.py", line 538, in _stringify_state
    if (state := self.state) is None:
  File "/usr/src/homeassistant/homeassistant/components/sensor/__init__.py", line 388, in state
    value = self.native_value
  File "/usr/src/homeassistant/homeassistant/components/pi_hole/sensor.py", line 69, in native_value
    return round(self.api.data[self.entity_description.key], 2)
KeyError: 'ads_blocked_today'
2022-07-27 21:28:03 ERROR (MainThread) [homeassistant] Error doing job: Task exception was never retrieved
Traceback (most recent call last):
  File "/usr/src/homeassistant/homeassistant/helpers/update_coordinator.py", line 151, in _handle_refresh_interval
    await self._async_refresh(log_failures=True, scheduled=True)
  File "/usr/src/homeassistant/homeassistant/helpers/update_coordinator.py", line 283, in _async_refresh
    self.async_update_listeners()
  File "/usr/src/homeassistant/homeassistant/helpers/update_coordinator.py", line 110, in async_update_listeners
    update_callback()
  File "/usr/src/homeassistant/homeassistant/helpers/update_coordinator.py", line 339, in _handle_coordinator_update
    self.async_write_ha_state()
  File "/usr/src/homeassistant/homeassistant/helpers/entity.py", line 532, in async_write_ha_state
    self._async_write_ha_state()
  File "/usr/src/homeassistant/homeassistant/helpers/entity.py", line 570, in _async_write_ha_state
    state = self._stringify_state(available)
  File "/usr/src/homeassistant/homeassistant/helpers/entity.py", line 538, in _stringify_state
    if (state := self.state) is None:
  File "/usr/src/homeassistant/homeassistant/components/sensor/__init__.py", line 388, in state
    value = self.native_value
  File "/usr/src/homeassistant/homeassistant/components/pi_hole/sensor.py", line 69, in native_value
    return round(self.api.data[self.entity_description.key], 2)
KeyError: 'ads_blocked_today'
2022-07-27 21:33:03 ERROR (MainThread) [homeassistant] Error doing job: Task exception was never retrieved
Traceback (most recent call last):
  File "/usr/src/homeassistant/homeassistant/helpers/update_coordinator.py", line 151, in _handle_refresh_interval
    await self._async_refresh(log_failures=True, scheduled=True)
  File "/usr/src/homeassistant/homeassistant/helpers/update_coordinator.py", line 283, in _async_refresh
    self.async_update_listeners()
  File "/usr/src/homeassistant/homeassistant/helpers/update_coordinator.py", line 110, in async_update_listeners
    update_callback()
  File "/usr/src/homeassistant/homeassistant/helpers/update_coordinator.py", line 339, in _handle_coordinator_update
    self.async_write_ha_state()
  File "/usr/src/homeassistant/homeassistant/helpers/entity.py", line 532, in async_write_ha_state
    self._async_write_ha_state()
  File "/usr/src/homeassistant/homeassistant/helpers/entity.py", line 570, in _async_write_ha_state
    state = self._stringify_state(available)
  File "/usr/src/homeassistant/homeassistant/helpers/entity.py", line 538, in _stringify_state
    if (state := self.state) is None:
  File "/usr/src/homeassistant/homeassistant/components/sensor/__init__.py", line 388, in state
    value = self.native_value
  File "/usr/src/homeassistant/homeassistant/components/pi_hole/sensor.py", line 69, in native_value
    return round(self.api.data[self.entity_description.key], 2)
KeyError: 'ads_blocked_today'
2022-07-27 21:38:03 ERROR (MainThread) [homeassistant] Error doing job: Task exception was never retrieved
Traceback (most recent call last):
  File "/usr/src/homeassistant/homeassistant/helpers/update_coordinator.py", line 151, in _handle_refresh_interval
    await self._async_refresh(log_failures=True, scheduled=True)
  File "/usr/src/homeassistant/homeassistant/helpers/update_coordinator.py", line 283, in _async_refresh
    self.async_update_listeners()
  File "/usr/src/homeassistant/homeassistant/helpers/update_coordinator.py", line 110, in async_update_listeners
    update_callback()
  File "/usr/src/homeassistant/homeassistant/helpers/update_coordinator.py", line 339, in _handle_coordinator_update
    self.async_write_ha_state()
  File "/usr/src/homeassistant/homeassistant/helpers/entity.py", line 532, in async_write_ha_state
    self._async_write_ha_state()
  File "/usr/src/homeassistant/homeassistant/helpers/entity.py", line 570, in _async_write_ha_state
    state = self._stringify_state(available)
  File "/usr/src/homeassistant/homeassistant/helpers/entity.py", line 538, in _stringify_state
    if (state := self.state) is None:
  File "/usr/src/homeassistant/homeassistant/components/sensor/__init__.py", line 388, in state
    value = self.native_value
  File "/usr/src/homeassistant/homeassistant/components/pi_hole/sensor.py", line 69, in native_value
    return round(self.api.data[self.entity_description.key], 2)
KeyError: 'ads_blocked_today'
2022-07-27 21:39:34 WARNING (SyncWorker_7) [homeassistant.components.rpi_power.binary_sensor] Under-voltage was detected. Consider getting a uninterruptible power supply for your Raspberry Pi.
2022-07-27 21:43:03 ERROR (MainThread) [homeassistant] Error doing job: Task exception was never retrieved
Traceback (most recent call last):
  File "/usr/src/homeassistant/homeassistant/helpers/update_coordinator.py", line 151, in _handle_refresh_interval
    await self._async_refresh(log_failures=True, scheduled=True)
  File "/usr/src/homeassistant/homeassistant/helpers/update_coordinator.py", line 283, in _async_refresh
    self.async_update_listeners()
  File "/usr/src/homeassistant/homeassistant/helpers/update_coordinator.py", line 110, in async_update_listeners
    update_callback()
  File "/usr/src/homeassistant/homeassistant/helpers/update_coordinator.py", line 339, in _handle_coordinator_update
    self.async_write_ha_state()
  File "/usr/src/homeassistant/homeassistant/helpers/entity.py", line 532, in async_write_ha_state
    self._async_write_ha_state()
  File "/usr/src/homeassistant/homeassistant/helpers/entity.py", line 570, in _async_write_ha_state
    state = self._stringify_state(available)
  File "/usr/src/homeassistant/homeassistant/helpers/entity.py", line 538, in _stringify_state
    if (state := self.state) is None:
  File "/usr/src/homeassistant/homeassistant/components/sensor/__init__.py", line 388, in state
    value = self.native_value
  File "/usr/src/homeassistant/homeassistant/components/pi_hole/sensor.py", line 69, in native_value
    return round(self.api.data[self.entity_description.key], 2)
KeyError: 'ads_blocked_today'
2022-07-27 21:48:03 ERROR (MainThread) [homeassistant] Error doing job: Task exception was never retrieved
Traceback (most recent call last):
  File "/usr/src/homeassistant/homeassistant/helpers/update_coordinator.py", line 151, in _handle_refresh_interval
    await self._async_refresh(log_failures=True, scheduled=True)
  File "/usr/src/homeassistant/homeassistant/helpers/update_coordinator.py", line 283, in _async_refresh
    self.async_update_listeners()
  File "/usr/src/homeassistant/homeassistant/helpers/update_coordinator.py", line 110, in async_update_listeners
    update_callback()
  File "/usr/src/homeassistant/homeassistant/helpers/update_coordinator.py", line 339, in _handle_coordinator_update
    self.async_write_ha_state()
  File "/usr/src/homeassistant/homeassistant/helpers/entity.py", line 532, in async_write_ha_state
    self._async_write_ha_state()
  File "/usr/src/homeassistant/homeassistant/helpers/entity.py", line 570, in _async_write_ha_state
    state = self._stringify_state(available)
  File "/usr/src/homeassistant/homeassistant/helpers/entity.py", line 538, in _stringify_state
    if (state := self.state) is None:
  File "/usr/src/homeassistant/homeassistant/components/sensor/__init__.py", line 388, in state
    value = self.native_value
  File "/usr/src/homeassistant/homeassistant/components/pi_hole/sensor.py", line 69, in native_value
    return round(self.api.data[self.entity_description.key], 2)
KeyError: 'ads_blocked_today'
2022-07-27 21:53:03 ERROR (MainThread) [homeassistant] Error doing job: Task exception was never retrieved
Traceback (most recent call last):
  File "/usr/src/homeassistant/homeassistant/helpers/update_coordinator.py", line 151, in _handle_refresh_interval
    await self._async_refresh(log_failures=True, scheduled=True)
  File "/usr/src/homeassistant/homeassistant/helpers/update_coordinator.py", line 283, in _async_refresh
    self.async_update_listeners()
  File "/usr/src/homeassistant/homeassistant/helpers/update_coordinator.py", line 110, in async_update_listeners
    update_callback()
  File "/usr/src/homeassistant/homeassistant/helpers/update_coordinator.py", line 339, in _handle_coordinator_update
    self.async_write_ha_state()
  File "/usr/src/homeassistant/homeassistant/helpers/entity.py", line 532, in async_write_ha_state
    self._async_write_ha_state()
  File "/usr/src/homeassistant/homeassistant/helpers/entity.py", line 570, in _async_write_ha_state
    state = self._stringify_state(available)
  File "/usr/src/homeassistant/homeassistant/helpers/entity.py", line 538, in _stringify_state
    if (state := self.state) is None:
  File "/usr/src/homeassistant/homeassistant/components/sensor/__init__.py", line 388, in state
    value = self.native_value
  File "/usr/src/homeassistant/homeassistant/components/pi_hole/sensor.py", line 69, in native_value
    return round(self.api.data[self.entity_description.key], 2)
KeyError: 'ads_blocked_today'
2022-07-27 21:58:03 ERROR (MainThread) [homeassistant] Error doing job: Task exception was never retrieved
Traceback (most recent call last):
  File "/usr/src/homeassistant/homeassistant/helpers/update_coordinator.py", line 151, in _handle_refresh_interval
    await self._async_refresh(log_failures=True, scheduled=True)
  File "/usr/src/homeassistant/homeassistant/helpers/update_coordinator.py", line 283, in _async_refresh
    self.async_update_listeners()
  File "/usr/src/homeassistant/homeassistant/helpers/update_coordinator.py", line 110, in async_update_listeners
    update_callback()
  File "/usr/src/homeassistant/homeassistant/helpers/update_coordinator.py", line 339, in _handle_coordinator_update
    self.async_write_ha_state()
  File "/usr/src/homeassistant/homeassistant/helpers/entity.py", line 532, in async_write_ha_state
    self._async_write_ha_state()
  File "/usr/src/homeassistant/homeassistant/helpers/entity.py", line 570, in _async_write_ha_state
    state = self._stringify_state(available)
  File "/usr/src/homeassistant/homeassistant/helpers/entity.py", line 538, in _stringify_state
    if (state := self.state) is None:
  File "/usr/src/homeassistant/homeassistant/components/sensor/__init__.py", line 388, in state
    value = self.native_value
  File "/usr/src/homeassistant/homeassistant/components/pi_hole/sensor.py", line 69, in native_value
    return round(self.api.data[self.entity_description.key], 2)
KeyError: 'ads_blocked_today'
2022-07-27 22:03:03 ERROR (MainThread) [homeassistant] Error doing job: Task exception was never retrieved
Traceback (most recent call last):
  File "/usr/src/homeassistant/homeassistant/helpers/update_coordinator.py", line 151, in _handle_refresh_interval
    await self._async_refresh(log_failures=True, scheduled=True)
  File "/usr/src/homeassistant/homeassistant/helpers/update_coordinator.py", line 283, in _async_refresh
    self.async_update_listeners()
  File "/usr/src/homeassistant/homeassistant/helpers/update_coordinator.py", line 110, in async_update_listeners
    update_callback()
  File "/usr/src/homeassistant/homeassistant/helpers/update_coordinator.py", line 339, in _handle_coordinator_update
    self.async_write_ha_state()
  File "/usr/src/homeassistant/homeassistant/helpers/entity.py", line 532, in async_write_ha_state
    self._async_write_ha_state()
  File "/usr/src/homeassistant/homeassistant/helpers/entity.py", line 570, in _async_write_ha_state
    state = self._stringify_state(available)
  File "/usr/src/homeassistant/homeassistant/helpers/entity.py", line 538, in _stringify_state
    if (state := self.state) is None:
  File "/usr/src/homeassistant/homeassistant/components/sensor/__init__.py", line 388, in state
    value = self.native_value
  File "/usr/src/homeassistant/homeassistant/components/pi_hole/sensor.py", line 69, in native_value
    return round(self.api.data[self.entity_description.key], 2)
KeyError: 'ads_blocked_today'
2022-07-27 22:08:03 ERROR (MainThread) [homeassistant] Error doing job: Task exception was never retrieved
Traceback (most recent call last):
  File "/usr/src/homeassistant/homeassistant/helpers/update_coordinator.py", line 151, in _handle_refresh_interval
    await self._async_refresh(log_failures=True, scheduled=True)
  File "/usr/src/homeassistant/homeassistant/helpers/update_coordinator.py", line 283, in _async_refresh
    self.async_update_listeners()
  File "/usr/src/homeassistant/homeassistant/helpers/update_coordinator.py", line 110, in async_update_listeners
    update_callback()
  File "/usr/src/homeassistant/homeassistant/helpers/update_coordinator.py", line 339, in _handle_coordinator_update
    self.async_write_ha_state()
  File "/usr/src/homeassistant/homeassistant/helpers/entity.py", line 532, in async_write_ha_state
    self._async_write_ha_state()
  File "/usr/src/homeassistant/homeassistant/helpers/entity.py", line 570, in _async_write_ha_state
    state = self._stringify_state(available)
  File "/usr/src/homeassistant/homeassistant/helpers/entity.py", line 538, in _stringify_state
    if (state := self.state) is None:
  File "/usr/src/homeassistant/homeassistant/components/sensor/__init__.py", line 388, in state
    value = self.native_value
  File "/usr/src/homeassistant/homeassistant/components/pi_hole/sensor.py", line 69, in native_value
    return round(self.api.data[self.entity_description.key], 2)
KeyError: 'ads_blocked_today'
2022-07-27 22:13:03 ERROR (MainThread) [homeassistant] Error doing job: Task exception was never retrieved
Traceback (most recent call last):
  File "/usr/src/homeassistant/homeassistant/helpers/update_coordinator.py", line 151, in _handle_refresh_interval
    await self._async_refresh(log_failures=True, scheduled=True)
  File "/usr/src/homeassistant/homeassistant/helpers/update_coordinator.py", line 283, in _async_refresh
    self.async_update_listeners()
  File "/usr/src/homeassistant/homeassistant/helpers/update_coordinator.py", line 110, in async_update_listeners
    update_callback()
  File "/usr/src/homeassistant/homeassistant/helpers/update_coordinator.py", line 339, in _handle_coordinator_update
    self.async_write_ha_state()
  File "/usr/src/homeassistant/homeassistant/helpers/entity.py", line 532, in async_write_ha_state
    self._async_write_ha_state()
  File "/usr/src/homeassistant/homeassistant/helpers/entity.py", line 570, in _async_write_ha_state
    state = self._stringify_state(available)
  File "/usr/src/homeassistant/homeassistant/helpers/entity.py", line 538, in _stringify_state
    if (state := self.state) is None:
  File "/usr/src/homeassistant/homeassistant/components/sensor/__init__.py", line 388, in state
    value = self.native_value
  File "/usr/src/homeassistant/homeassistant/components/pi_hole/sensor.py", line 69, in native_value
    return round(self.api.data[self.entity_description.key], 2)
KeyError: 'ads_blocked_today'
2022-07-27 22:18:03 ERROR (MainThread) [homeassistant] Error doing job: Task exception was never retrieved
Traceback (most recent call last):
  File "/usr/src/homeassistant/homeassistant/helpers/update_coordinator.py", line 151, in _handle_refresh_interval
    await self._async_refresh(log_failures=True, scheduled=True)
  File "/usr/src/homeassistant/homeassistant/helpers/update_coordinator.py", line 283, in _async_refresh
    self.async_update_listeners()
  File "/usr/src/homeassistant/homeassistant/helpers/update_coordinator.py", line 110, in async_update_listeners
    update_callback()
  File "/usr/src/homeassistant/homeassistant/helpers/update_coordinator.py", line 339, in _handle_coordinator_update
    self.async_write_ha_state()
  File "/usr/src/homeassistant/homeassistant/helpers/entity.py", line 532, in async_write_ha_state
    self._async_write_ha_state()
  File "/usr/src/homeassistant/homeassistant/helpers/entity.py", line 570, in _async_write_ha_state
    state = self._stringify_state(available)
  File "/usr/src/homeassistant/homeassistant/helpers/entity.py", line 538, in _stringify_state
    if (state := self.state) is None:
  File "/usr/src/homeassistant/homeassistant/components/sensor/__init__.py", line 388, in state
    value = self.native_value
  File "/usr/src/homeassistant/homeassistant/components/pi_hole/sensor.py", line 69, in native_value
    return round(self.api.data[self.entity_description.key], 2)
KeyError: 'ads_blocked_today'
2022-07-27 22:23:08 ERROR (MainThread) [hole] Can not load data from *hole: 192.168.1.150:80
2022-07-27 22:23:08 ERROR (MainThread) [homeassistant.components.pi_hole] Error fetching Pi-Hole data: Failed to communicate with API: Can not load data from *hole: 192.168.1.150:80
2022-07-27 22:28:08 ERROR (MainThread) [hole] Can not load data from *hole: 192.168.1.150:80
2022-07-27 22:33:08 ERROR (MainThread) [hole] Can not load data from *hole: 192.168.1.150:80
2022-07-27 22:38:08 ERROR (MainThread) [hole] Can not load data from *hole: 192.168.1.150:80
2022-07-27 22:43:08 ERROR (MainThread) [hole] Can not load data from *hole: 192.168.1.150:80
2022-07-27 22:47:33 ERROR (MainThread) [homeassistant.components.upnp] Error fetching RT-AX88-Cramacug data: Unable to communicate with IGD at: http://192.168.1.1:44479/rootDesc.xml
2022-07-27 22:48:04 WARNING (SyncWorker_6) [homeassistant.components.rpi_power.binary_sensor] Under-voltage was detected. Consider getting a uninterruptible power supply for your Raspberry Pi.
2022-07-27 22:48:08 ERROR (MainThread) [hole] Can not load data from *hole: 192.168.1.150:80
2022-07-27 22:53:08 ERROR (MainThread) [hole] Can not load data from *hole: 192.168.1.150:80
2022-07-27 22:58:08 ERROR (MainThread) [hole] Can not load data from *hole: 192.168.1.150:80
2022-07-27 23:03:08 ERROR (MainThread) [hole] Can not load data from *hole: 192.168.1.150:80
2022-07-27 23:03:08 ERROR (MainThread) [metno] Access to https://aa015h6buqvih86i1.api.met.no/weatherapi/locationforecast/2.0/complete returned error 'ClientConnectorError'
2022-07-27 23:03:08 ERROR (MainThread) [homeassistant.components.met] Error fetching met data: Update failed: 
2022-07-27 23:08:08 ERROR (MainThread) [hole] Can not load data from *hole: 192.168.1.150:80
2022-07-27 23:13:08 ERROR (MainThread) [hole] Can not load data from *hole: 192.168.1.150:80
2022-07-27 23:18:08 ERROR (MainThread) [hole] Can not load data from *hole: 192.168.1.150:80
2022-07-27 23:23:08 ERROR (MainThread) [hole] Can not load data from *hole: 192.168.1.150:80
2022-07-27 23:28:08 ERROR (MainThread) [hole] Can not load data from *hole: 192.168.1.150:80
2022-07-27 23:33:08 ERROR (MainThread) [hole] Can not load data from *hole: 192.168.1.150:80
2022-07-27 23:38:08 ERROR (MainThread) [hole] Can not load data from *hole: 192.168.1.150:80
2022-07-27 23:40:16 ERROR (MainThread) [hole] Can not load data from *hole: http://192.168.1.155:37545
2022-07-27 23:40:20 ERROR (MainThread) [hole] Can not load data from *hole: http://192.168.1.155:37545
2022-07-27 23:40:27 ERROR (MainThread) [hole] Can not load data from *hole: http://192.168.1.155:37545
2022-07-28 00:42:04 WARNING (SyncWorker_4) [homeassistant.components.rpi_power.binary_sensor] Under-voltage was detected. Consider getting a uninterruptible power supply for your Raspberry Pi.
2022-07-28 01:40:04 WARNING (SyncWorker_6) [homeassistant.components.rpi_power.binary_sensor] Under-voltage was detected. Consider getting a uninterruptible power supply for your Raspberry Pi.
2022-07-28 02:35:35 WARNING (SyncWorker_5) [homeassistant.components.rpi_power.binary_sensor] Under-voltage was detected. Consider getting a uninterruptible power supply for your Raspberry Pi.
2022-07-28 02:38:35 WARNING (SyncWorker_2) [homeassistant.components.rpi_power.binary_sensor] Under-voltage was detected. Consider getting a uninterruptible power supply for your Raspberry Pi.
2022-07-28 03:27:05 WARNING (SyncWorker_4) [homeassistant.components.rpi_power.binary_sensor] Under-voltage was detected. Consider getting a uninterruptible power supply for your Raspberry Pi.
2022-07-28 03:39:05 WARNING (SyncWorker_6) [homeassistant.components.rpi_power.binary_sensor] Under-voltage was detected. Consider getting a uninterruptible power supply for your Raspberry Pi.
2022-07-28 04:56:05 WARNING (SyncWorker_5) [homeassistant.components.rpi_power.binary_sensor] Under-voltage was detected. Consider getting a uninterruptible power supply for your Raspberry Pi.
2022-07-28 04:57:35 WARNING (SyncWorker_7) [homeassistant.components.rpi_power.binary_sensor] Under-voltage was detected. Consider getting a uninterruptible power supply for your Raspberry Pi.
2022-07-28 05:30:35 WARNING (SyncWorker_4) [homeassistant.components.rpi_power.binary_sensor] Under-voltage was detected. Consider getting a uninterruptible power supply for your Raspberry Pi.
2022-07-28 05:36:35 WARNING (SyncWorker_8) [homeassistant.components.rpi_power.binary_sensor] Under-voltage was detected. Consider getting a uninterruptible power supply for your Raspberry Pi.
2022-07-28 06:46:05 WARNING (SyncWorker_0) [homeassistant.components.rpi_power.binary_sensor] Under-voltage was detected. Consider getting a uninterruptible power supply for your Raspberry Pi.
2022-07-28 07:04:35 WARNING (SyncWorker_1) [homeassistant.components.rpi_power.binary_sensor] Under-voltage was detected. Consider getting a uninterruptible power supply for your Raspberry Pi.
2022-07-28 07:18:05 WARNING (SyncWorker_0) [homeassistant.components.rpi_power.binary_sensor] Under-voltage was detected. Consider getting a uninterruptible power supply for your Raspberry Pi.
2022-07-28 07:27:05 WARNING (SyncWorker_2) [homeassistant.components.rpi_power.binary_sensor] Under-voltage was detected. Consider getting a uninterruptible power supply for your Raspberry Pi.
2022-07-28 07:50:05 WARNING (SyncWorker_0) [homeassistant.components.rpi_power.binary_sensor] Under-voltage was detected. Consider getting a uninterruptible power supply for your Raspberry Pi.
2022-07-28 08:21:05 WARNING (SyncWorker_5) [homeassistant.components.rpi_power.binary_sensor] Under-voltage was detected. Consider getting a uninterruptible power supply for your Raspberry Pi.
2022-07-28 08:29:05 WARNING (SyncWorker_5) [homeassistant.components.rpi_power.binary_sensor] Under-voltage was detected. Consider getting a uninterruptible power supply for your Raspberry Pi.
2022-07-28 08:35:10 WARNING (Recorder) [homeassistant.components.sensor.recorder] Entity sensor.pool_energy from integration shelly has state class total_increasing, but its state is not strictly increasing. Triggered by state 29.37 (29.38) with last_updated set to 2022-07-28T06:30:37.793916+00:00. Please create a bug report at https://github.com/home-assistant/core/issues?q=is%3Aopen+is%3Aissue+label%3A%22integration%3A+shelly%22
2022-07-28 09:30:05 WARNING (SyncWorker_7) [homeassistant.components.rpi_power.binary_sensor] Under-voltage was detected. Consider getting a uninterruptible power supply for your Raspberry Pi.
2022-07-28 09:34:06 WARNING (SyncWorker_1) [homeassistant.components.rpi_power.binary_sensor] Under-voltage was detected. Consider getting a uninterruptible power supply for your Raspberry Pi.
2022-07-28 10:03:06 WARNING (SyncWorker_2) [homeassistant.components.rpi_power.binary_sensor] Under-voltage was detected. Consider getting a uninterruptible power supply for your Raspberry Pi.
2022-07-28 10:27:06 WARNING (SyncWorker_8) [homeassistant.components.rpi_power.binary_sensor] Under-voltage was detected. Consider getting a uninterruptible power supply for your Raspberry Pi.
2022-07-28 10:45:36 WARNING (SyncWorker_8) [homeassistant.components.rpi_power.binary_sensor] Under-voltage was detected. Consider getting a uninterruptible power supply for your Raspberry Pi.
2022-07-28 11:15:06 WARNING (SyncWorker_8) [homeassistant.components.rpi_power.binary_sensor] Under-voltage was detected. Consider getting a uninterruptible power supply for your Raspberry Pi.
2022-07-28 11:20:06 WARNING (SyncWorker_2) [homeassistant.components.rpi_power.binary_sensor] Under-voltage was detected. Consider getting a uninterruptible power supply for your Raspberry Pi.
2022-07-28 11:56:30 WARNING (MainThread) [homeassistant.components.websocket_api.http.connection] [547331648400] Disconnected: Did not receive auth message within 10 seconds
2022-07-28 12:39:06 WARNING (SyncWorker_2) [homeassistant.components.rpi_power.binary_sensor] Under-voltage was detected. Consider getting a uninterruptible power supply for your Raspberry Pi.
2022-07-28 13:09:06 WARNING (SyncWorker_4) [homeassistant.components.rpi_power.binary_sensor] Under-voltage was detected. Consider getting a uninterruptible power supply for your Raspberry Pi.
2022-07-28 13:20:36 WARNING (SyncWorker_4) [homeassistant.components.rpi_power.binary_sensor] Under-voltage was detected. Consider getting a uninterruptible power supply for your Raspberry Pi.
2022-07-28 14:03:06 WARNING (SyncWorker_4) [homeassistant.components.rpi_power.binary_sensor] Under-voltage was detected. Consider getting a uninterruptible power supply for your Raspberry Pi.
2022-07-28 14:51:06 WARNING (SyncWorker_1) [homeassistant.components.rpi_power.binary_sensor] Under-voltage was detected. Consider getting a uninterruptible power supply for your Raspberry Pi.
2022-07-28 14:54:06 WARNING (SyncWorker_2) [homeassistant.components.rpi_power.binary_sensor] Under-voltage was detected. Consider getting a uninterruptible power supply for your Raspberry Pi.
2022-07-28 15:51:36 WARNING (SyncWorker_8) [homeassistant.components.rpi_power.binary_sensor] Under-voltage was detected. Consider getting a uninterruptible power supply for your Raspberry Pi.
2022-07-28 15:53:36 WARNING (SyncWorker_2) [homeassistant.components.rpi_power.binary_sensor] Under-voltage was detected. Consider getting a uninterruptible power supply for your Raspberry Pi.
2022-07-28 15:54:41 ERROR (MainThread) [homeassistant.components.shelly] Error fetching Garden Shelly Hub data: Device disconnected
2022-07-28 16:01:06 WARNING (SyncWorker_4) [homeassistant.components.rpi_power.binary_sensor] Under-voltage was detected. Consider getting a uninterruptible power supply for your Raspberry Pi.
2022-07-28 16:38:37 WARNING (SyncWorker_0) [homeassistant.components.rpi_power.binary_sensor] Under-voltage was detected. Consider getting a uninterruptible power supply for your Raspberry Pi.
2022-07-28 16:46:37 WARNING (SyncWorker_2) [homeassistant.components.rpi_power.binary_sensor] Under-voltage was detected. Consider getting a uninterruptible power supply for your Raspberry Pi.
2022-07-28 16:59:37 WARNING (SyncWorker_5) [homeassistant.components.rpi_power.binary_sensor] Under-voltage was detected. Consider getting a uninterruptible power supply for your Raspberry Pi.
2022-07-28 17:00:37 WARNING (SyncWorker_0) [homeassistant.components.rpi_power.binary_sensor] Under-voltage was detected. Consider getting a uninterruptible power supply for your Raspberry Pi.
2022-07-28 17:44:37 WARNING (SyncWorker_0) [homeassistant.components.rpi_power.binary_sensor] Under-voltage was detected. Consider getting a uninterruptible power supply for your Raspberry Pi.
2022-07-28 17:48:37 WARNING (SyncWorker_4) [homeassistant.components.rpi_power.binary_sensor] Under-voltage was detected. Consider getting a uninterruptible power supply for your Raspberry Pi.
2022-07-28 17:57:07 WARNING (SyncWorker_0) [homeassistant.components.rpi_power.binary_sensor] Under-voltage was detected. Consider getting a uninterruptible power supply for your Raspberry Pi.
2022-07-28 18:59:07 WARNING (SyncWorker_6) [homeassistant.components.rpi_power.binary_sensor] Under-voltage was detected. Consider getting a uninterruptible power supply for your Raspberry Pi.
2022-07-28 19:13:07 WARNING (SyncWorker_8) [homeassistant.components.rpi_power.binary_sensor] Under-voltage was detected. Consider getting a uninterruptible power supply for your Raspberry Pi.
2022-07-28 19:51:37 WARNING (SyncWorker_0) [homeassistant.components.rpi_power.binary_sensor] Under-voltage was detected. Consider getting a uninterruptible power supply for your Raspberry Pi.
2022-07-28 19:59:37 WARNING (SyncWorker_8) [homeassistant.components.rpi_power.binary_sensor] Under-voltage was detected. Consider getting a uninterruptible power supply for your Raspberry Pi.
2022-07-28 20:35:02 WARNING (MainThread) [homeassistant.components.websocket_api.http.connection] [547684190768] Disconnected: Did not receive auth message within 10 seconds
2022-07-28 20:43:37 WARNING (SyncWorker_7) [homeassistant.components.rpi_power.binary_sensor] Under-voltage was detected. Consider getting a uninterruptible power supply for your Raspberry Pi.
2022-07-28 20:46:37 WARNING (SyncWorker_2) [homeassistant.components.rpi_power.binary_sensor] Under-voltage was detected. Consider getting a uninterruptible power supply for your Raspberry Pi.
2022-07-28 21:17:07 WARNING (SyncWorker_7) [homeassistant.components.rpi_power.binary_sensor] Under-voltage was detected. Consider getting a uninterruptible power supply for your Raspberry Pi.
2022-07-28 22:04:37 WARNING (SyncWorker_7) [homeassistant.components.rpi_power.binary_sensor] Under-voltage was detected. Consider getting a uninterruptible power supply for your Raspberry Pi.
2022-07-28 22:24:07 WARNING (SyncWorker_3) [homeassistant.components.rpi_power.binary_sensor] Under-voltage was detected. Consider getting a uninterruptible power supply for your Raspberry Pi.
2022-07-28 22:30:07 WARNING (SyncWorker_2) [homeassistant.components.rpi_power.binary_sensor] Under-voltage was detected. Consider getting a uninterruptible power supply for your Raspberry Pi.
2022-07-28 22:43:07 WARNING (SyncWorker_2) [homeassistant.components.rpi_power.binary_sensor] Under-voltage was detected. Consider getting a uninterruptible power supply for your Raspberry Pi.
2022-07-28 22:49:07 WARNING (SyncWorker_2) [homeassistant.components.rpi_power.binary_sensor] Under-voltage was detected. Consider getting a uninterruptible power supply for your Raspberry Pi.
2022-07-28 23:24:38 WARNING (SyncWorker_5) [homeassistant.components.rpi_power.binary_sensor] Under-voltage was detected. Consider getting a uninterruptible power supply for your Raspberry Pi.
2022-07-28 23:58:38 WARNING (SyncWorker_4) [homeassistant.components.rpi_power.binary_sensor] Under-voltage was detected. Consider getting a uninterruptible power supply for your Raspberry Pi.
2022-07-29 00:12:57 WARNING (MainThread) [homeassistant.components.websocket_api.http.connection] [547298138464] Disconnected: Did not receive auth message within 10 seconds
2022-07-29 00:50:39 WARNING (MainThread) [homeassistant.components.websocket_api.http.connection] [547297192608] Disconnected: Did not receive auth message within 10 seconds
2022-07-29 01:33:08 WARNING (SyncWorker_7) [homeassistant.components.rpi_power.binary_sensor] Under-voltage was detected. Consider getting a uninterruptible power supply for your Raspberry Pi.
2022-07-29 01:58:27 WARNING (MainThread) [homeassistant.components.websocket_api.http.connection] [547297805072] Disconnected: Did not receive auth message within 10 seconds
2022-07-29 02:37:38 WARNING (SyncWorker_7) [homeassistant.components.rpi_power.binary_sensor] Under-voltage was detected. Consider getting a uninterruptible power supply for your Raspberry Pi.
2022-07-29 02:47:08 WARNING (SyncWorker_6) [homeassistant.components.rpi_power.binary_sensor] Under-voltage was detected. Consider getting a uninterruptible power supply for your Raspberry Pi.
2022-07-29 04:18:38 WARNING (SyncWorker_3) [homeassistant.components.rpi_power.binary_sensor] Under-voltage was detected. Consider getting a uninterruptible power supply for your Raspberry Pi.
2022-07-29 05:29:09 WARNING (SyncWorker_7) [homeassistant.components.rpi_power.binary_sensor] Under-voltage was detected. Consider getting a uninterruptible power supply for your Raspberry Pi.
2022-07-29 06:16:39 WARNING (SyncWorker_2) [homeassistant.components.rpi_power.binary_sensor] Under-voltage was detected. Consider getting a uninterruptible power supply for your Raspberry Pi.
2022-07-29 07:15:09 WARNING (SyncWorker_0) [homeassistant.components.rpi_power.binary_sensor] Under-voltage was detected. Consider getting a uninterruptible power supply for your Raspberry Pi.
2022-07-29 07:17:39 WARNING (SyncWorker_4) [homeassistant.components.rpi_power.binary_sensor] Under-voltage was detected. Consider getting a uninterruptible power supply for your Raspberry Pi.
2022-07-29 07:46:06 ERROR (MainThread) [homeassistant.components.shelly] Error fetching Garden Shelly Hub data: Device disconnected
2022-07-29 08:00:39 WARNING (SyncWorker_8) [homeassistant.components.rpi_power.binary_sensor] Under-voltage was detected. Consider getting a uninterruptible power supply for your Raspberry Pi.
2022-07-29 08:45:09 WARNING (SyncWorker_1) [homeassistant.components.rpi_power.binary_sensor] Under-voltage was detected. Consider getting a uninterruptible power supply for your Raspberry Pi.
2022-07-29 09:13:39 WARNING (SyncWorker_1) [homeassistant.components.rpi_power.binary_sensor] Under-voltage was detected. Consider getting a uninterruptible power supply for your Raspberry Pi.
2022-07-29 09:29:09 WARNING (SyncWorker_1) [homeassistant.components.rpi_power.binary_sensor] Under-voltage was detected. Consider getting a uninterruptible power supply for your Raspberry Pi.
2022-07-29 10:19:36 WARNING (MainThread) [homeassistant.components.websocket_api.http.connection] [547318947584] Disconnected: Did not receive auth message within 10 seconds
2022-07-29 10:26:39 WARNING (SyncWorker_0) [homeassistant.components.rpi_power.binary_sensor] Under-voltage was detected. Consider getting a uninterruptible power supply for your Raspberry Pi.
2022-07-29 11:38:40 WARNING (SyncWorker_3) [homeassistant.components.rpi_power.binary_sensor] Under-voltage was detected. Consider getting a uninterruptible power supply for your Raspberry Pi.
2022-07-29 12:08:40 WARNING (SyncWorker_1) [homeassistant.components.rpi_power.binary_sensor] Under-voltage was detected. Consider getting a uninterruptible power supply for your Raspberry Pi.
2022-07-29 12:43:40 WARNING (SyncWorker_7) [homeassistant.components.rpi_power.binary_sensor] Under-voltage was detected. Consider getting a uninterruptible power supply for your Raspberry Pi.
